[2024-02-13T16:46:04.774+0000] {taskinstance.py:1956} INFO - Dependencies all met for dep_context=non-requeueable deps ti=<TaskInstance: deverlop_model.data_sets scheduled__2022-01-01T01:05:00+00:00 [queued]>
[2024-02-13T16:46:04.784+0000] {taskinstance.py:1956} INFO - Dependencies all met for dep_context=requeueable deps ti=<TaskInstance: deverlop_model.data_sets scheduled__2022-01-01T01:05:00+00:00 [queued]>
[2024-02-13T16:46:04.785+0000] {taskinstance.py:2170} INFO - Starting attempt 1 of 1
[2024-02-13T16:46:04.800+0000] {taskinstance.py:2191} INFO - Executing <Task(DockerOperator): data_sets> on 2022-01-01 01:05:00+00:00
[2024-02-13T16:46:04.811+0000] {standard_task_runner.py:60} INFO - Started process 699 to run task
[2024-02-13T16:46:04.815+0000] {standard_task_runner.py:87} INFO - Running: ['***', 'tasks', 'run', 'deverlop_model', 'data_sets', 'scheduled__2022-01-01T01:05:00+00:00', '--job-id', '55', '--raw', '--subdir', 'DAGS_FOLDER/task.py', '--cfg-path', '/tmp/tmpiraj0sek']
[2024-02-13T16:46:04.818+0000] {standard_task_runner.py:88} INFO - Job 55: Subtask data_sets
[2024-02-13T16:46:04.872+0000] {task_command.py:423} INFO - Running <TaskInstance: deverlop_model.data_sets scheduled__2022-01-01T01:05:00+00:00 [running]> on host a5e5e25b3882
[2024-02-13T16:46:04.948+0000] {taskinstance.py:2480} INFO - Exporting env vars: AIRFLOW_CTX_DAG_OWNER='rtn' AIRFLOW_CTX_DAG_ID='deverlop_model' AIRFLOW_CTX_TASK_ID='data_sets' AIRFLOW_CTX_EXECUTION_DATE='2022-01-01T01:05:00+00:00' AIRFLOW_CTX_TRY_NUMBER='1' AIRFLOW_CTX_DAG_RUN_ID='scheduled__2022-01-01T01:05:00+00:00'
[2024-02-13T16:46:04.967+0000] {docker.py:359} INFO - Starting docker container from image python:3.8
[2024-02-13T16:46:04.972+0000] {taskinstance.py:2698} ERROR - Task failed with exception
Traceback (most recent call last):
  File "/home/airflow/.local/lib/python3.8/site-packages/docker/api/client.py", line 265, in _raise_for_status
    response.raise_for_status()
  File "/home/airflow/.local/lib/python3.8/site-packages/requests/models.py", line 1021, in raise_for_status
    raise HTTPError(http_error_msg, response=self)
requests.exceptions.HTTPError: 409 Client Error: Conflict for url: http+docker://localhost/v1.43/containers/create?name=data_sets

The above exception was the direct cause of the following exception:

Traceback (most recent call last):
  File "/home/airflow/.local/lib/python3.8/site-packages/airflow/models/taskinstance.py", line 433, in _execute_task
    result = execute_callable(context=context, **execute_callable_kwargs)
  File "/home/airflow/.local/lib/python3.8/site-packages/airflow/providers/docker/operators/docker.py", line 502, in execute
    return self._run_image()
  File "/home/airflow/.local/lib/python3.8/site-packages/airflow/providers/docker/operators/docker.py", line 376, in _run_image
    return self._run_image_with_mounts(self.mounts, add_tmp_variable=False)
  File "/home/airflow/.local/lib/python3.8/site-packages/airflow/providers/docker/operators/docker.py", line 391, in _run_image_with_mounts
    self.container = self.cli.create_container(
  File "/home/airflow/.local/lib/python3.8/site-packages/docker/api/container.py", line 439, in create_container
    return self.create_container_from_config(config, name, platform)
  File "/home/airflow/.local/lib/python3.8/site-packages/docker/api/container.py", line 456, in create_container_from_config
    return self._result(res, True)
  File "/home/airflow/.local/lib/python3.8/site-packages/docker/api/client.py", line 271, in _result
    self._raise_for_status(response)
  File "/home/airflow/.local/lib/python3.8/site-packages/docker/api/client.py", line 267, in _raise_for_status
    raise create_api_error_from_http_exception(e) from e
  File "/home/airflow/.local/lib/python3.8/site-packages/docker/errors.py", line 39, in create_api_error_from_http_exception
    raise cls(e, response=response, explanation=explanation) from e
docker.errors.APIError: 409 Client Error for http+docker://localhost/v1.43/containers/create?name=data_sets: Conflict ("Conflict. The container name "/data_sets" is already in use by container "5897ff515172f4f41c925f4c699043628da1875224eecb14b7365e8021207ca9". You have to remove (or rename) that container to be able to reuse that name.")
[2024-02-13T16:46:04.981+0000] {taskinstance.py:1138} INFO - Marking task as FAILED. dag_id=deverlop_model, task_id=data_sets, execution_date=20220101T010500, start_date=20240213T164604, end_date=20240213T164604
[2024-02-13T16:46:04.992+0000] {standard_task_runner.py:107} ERROR - Failed to execute job 55 for task data_sets (409 Client Error for http+docker://localhost/v1.43/containers/create?name=data_sets: Conflict ("Conflict. The container name "/data_sets" is already in use by container "5897ff515172f4f41c925f4c699043628da1875224eecb14b7365e8021207ca9". You have to remove (or rename) that container to be able to reuse that name."); 699)
[2024-02-13T16:46:05.027+0000] {local_task_job_runner.py:234} INFO - Task exited with return code 1
[2024-02-13T16:46:05.048+0000] {taskinstance.py:3280} INFO - 0 downstream tasks scheduled from follow-on schedule check
[2024-02-13T16:47:35.317+0000] {taskinstance.py:1956} INFO - Dependencies all met for dep_context=non-requeueable deps ti=<TaskInstance: deverlop_model.data_sets scheduled__2022-01-01T01:05:00+00:00 [queued]>
[2024-02-13T16:47:35.331+0000] {taskinstance.py:1956} INFO - Dependencies all met for dep_context=requeueable deps ti=<TaskInstance: deverlop_model.data_sets scheduled__2022-01-01T01:05:00+00:00 [queued]>
[2024-02-13T16:47:35.332+0000] {taskinstance.py:2170} INFO - Starting attempt 1 of 1
[2024-02-13T16:47:35.345+0000] {taskinstance.py:2191} INFO - Executing <Task(DockerOperator): data_sets> on 2022-01-01 01:05:00+00:00
[2024-02-13T16:47:35.354+0000] {standard_task_runner.py:60} INFO - Started process 826 to run task
[2024-02-13T16:47:35.357+0000] {standard_task_runner.py:87} INFO - Running: ['***', 'tasks', 'run', 'deverlop_model', 'data_sets', 'scheduled__2022-01-01T01:05:00+00:00', '--job-id', '87', '--raw', '--subdir', 'DAGS_FOLDER/task.py', '--cfg-path', '/tmp/tmp4l76z3eo']
[2024-02-13T16:47:35.360+0000] {standard_task_runner.py:88} INFO - Job 87: Subtask data_sets
[2024-02-13T16:47:35.404+0000] {task_command.py:423} INFO - Running <TaskInstance: deverlop_model.data_sets scheduled__2022-01-01T01:05:00+00:00 [running]> on host a5e5e25b3882
[2024-02-13T16:47:35.465+0000] {taskinstance.py:2480} INFO - Exporting env vars: AIRFLOW_CTX_DAG_OWNER='rtn' AIRFLOW_CTX_DAG_ID='deverlop_model' AIRFLOW_CTX_TASK_ID='data_sets' AIRFLOW_CTX_EXECUTION_DATE='2022-01-01T01:05:00+00:00' AIRFLOW_CTX_TRY_NUMBER='1' AIRFLOW_CTX_DAG_RUN_ID='scheduled__2022-01-01T01:05:00+00:00'
[2024-02-13T16:47:35.482+0000] {docker.py:359} INFO - Starting docker container from image python:3.8
[2024-02-13T16:47:35.486+0000] {taskinstance.py:2698} ERROR - Task failed with exception
Traceback (most recent call last):
  File "/home/airflow/.local/lib/python3.8/site-packages/docker/api/client.py", line 265, in _raise_for_status
    response.raise_for_status()
  File "/home/airflow/.local/lib/python3.8/site-packages/requests/models.py", line 1021, in raise_for_status
    raise HTTPError(http_error_msg, response=self)
requests.exceptions.HTTPError: 409 Client Error: Conflict for url: http+docker://localhost/v1.43/containers/create?name=data_sets

The above exception was the direct cause of the following exception:

Traceback (most recent call last):
  File "/home/airflow/.local/lib/python3.8/site-packages/airflow/models/taskinstance.py", line 433, in _execute_task
    result = execute_callable(context=context, **execute_callable_kwargs)
  File "/home/airflow/.local/lib/python3.8/site-packages/airflow/providers/docker/operators/docker.py", line 502, in execute
    return self._run_image()
  File "/home/airflow/.local/lib/python3.8/site-packages/airflow/providers/docker/operators/docker.py", line 376, in _run_image
    return self._run_image_with_mounts(self.mounts, add_tmp_variable=False)
  File "/home/airflow/.local/lib/python3.8/site-packages/airflow/providers/docker/operators/docker.py", line 391, in _run_image_with_mounts
    self.container = self.cli.create_container(
  File "/home/airflow/.local/lib/python3.8/site-packages/docker/api/container.py", line 439, in create_container
    return self.create_container_from_config(config, name, platform)
  File "/home/airflow/.local/lib/python3.8/site-packages/docker/api/container.py", line 456, in create_container_from_config
    return self._result(res, True)
  File "/home/airflow/.local/lib/python3.8/site-packages/docker/api/client.py", line 271, in _result
    self._raise_for_status(response)
  File "/home/airflow/.local/lib/python3.8/site-packages/docker/api/client.py", line 267, in _raise_for_status
    raise create_api_error_from_http_exception(e) from e
  File "/home/airflow/.local/lib/python3.8/site-packages/docker/errors.py", line 39, in create_api_error_from_http_exception
    raise cls(e, response=response, explanation=explanation) from e
docker.errors.APIError: 409 Client Error for http+docker://localhost/v1.43/containers/create?name=data_sets: Conflict ("Conflict. The container name "/data_sets" is already in use by container "8359874ecdc2de6ff42b5f59860285d5315ee47d9f64e520a5617f04383ec00c". You have to remove (or rename) that container to be able to reuse that name.")
[2024-02-13T16:47:35.496+0000] {taskinstance.py:1138} INFO - Marking task as FAILED. dag_id=deverlop_model, task_id=data_sets, execution_date=20220101T010500, start_date=20240213T164735, end_date=20240213T164735
[2024-02-13T16:47:35.507+0000] {standard_task_runner.py:107} ERROR - Failed to execute job 87 for task data_sets (409 Client Error for http+docker://localhost/v1.43/containers/create?name=data_sets: Conflict ("Conflict. The container name "/data_sets" is already in use by container "8359874ecdc2de6ff42b5f59860285d5315ee47d9f64e520a5617f04383ec00c". You have to remove (or rename) that container to be able to reuse that name."); 826)
[2024-02-13T16:47:35.530+0000] {local_task_job_runner.py:234} INFO - Task exited with return code 1
[2024-02-13T16:47:35.551+0000] {taskinstance.py:3280} INFO - 0 downstream tasks scheduled from follow-on schedule check
