[2024-02-13T10:06:44.657+0000] {taskinstance.py:1956} INFO - Dependencies all met for dep_context=non-requeueable deps ti=<TaskInstance: deverlop_model.data_sets scheduled__2024-02-11T11:05:00+00:00 [queued]>
[2024-02-13T10:06:44.665+0000] {taskinstance.py:1956} INFO - Dependencies all met for dep_context=requeueable deps ti=<TaskInstance: deverlop_model.data_sets scheduled__2024-02-11T11:05:00+00:00 [queued]>
[2024-02-13T10:06:44.666+0000] {taskinstance.py:2170} INFO - Starting attempt 1 of 1
[2024-02-13T10:06:44.676+0000] {taskinstance.py:2191} INFO - Executing <Task(DockerOperator): data_sets> on 2024-02-11 11:05:00+00:00
[2024-02-13T10:06:44.684+0000] {standard_task_runner.py:60} INFO - Started process 1214 to run task
[2024-02-13T10:06:44.687+0000] {standard_task_runner.py:87} INFO - Running: ['***', 'tasks', 'run', 'deverlop_model', 'data_sets', 'scheduled__2024-02-11T11:05:00+00:00', '--job-id', '155', '--raw', '--subdir', 'DAGS_FOLDER/task.py', '--cfg-path', '/tmp/tmp_leuyzxt']
[2024-02-13T10:06:44.690+0000] {standard_task_runner.py:88} INFO - Job 155: Subtask data_sets
[2024-02-13T10:06:44.738+0000] {task_command.py:423} INFO - Running <TaskInstance: deverlop_model.data_sets scheduled__2024-02-11T11:05:00+00:00 [running]> on host 292a13d21cb7
[2024-02-13T10:06:44.804+0000] {taskinstance.py:2480} INFO - Exporting env vars: AIRFLOW_CTX_DAG_OWNER='rtn' AIRFLOW_CTX_DAG_ID='deverlop_model' AIRFLOW_CTX_TASK_ID='data_sets' AIRFLOW_CTX_EXECUTION_DATE='2024-02-11T11:05:00+00:00' AIRFLOW_CTX_TRY_NUMBER='1' AIRFLOW_CTX_DAG_RUN_ID='scheduled__2024-02-11T11:05:00+00:00'
[2024-02-13T10:06:44.821+0000] {docker.py:359} INFO - Starting docker container from image python:3.8
[2024-02-13T10:06:44.824+0000] {taskinstance.py:2698} ERROR - Task failed with exception
Traceback (most recent call last):
  File "/home/airflow/.local/lib/python3.8/site-packages/docker/api/client.py", line 265, in _raise_for_status
    response.raise_for_status()
  File "/home/airflow/.local/lib/python3.8/site-packages/requests/models.py", line 1021, in raise_for_status
    raise HTTPError(http_error_msg, response=self)
requests.exceptions.HTTPError: 409 Client Error: Conflict for url: http+docker://localhost/v1.43/containers/create?name=data_sets

The above exception was the direct cause of the following exception:

Traceback (most recent call last):
  File "/home/airflow/.local/lib/python3.8/site-packages/airflow/models/taskinstance.py", line 433, in _execute_task
    result = execute_callable(context=context, **execute_callable_kwargs)
  File "/home/airflow/.local/lib/python3.8/site-packages/airflow/providers/docker/operators/docker.py", line 502, in execute
    return self._run_image()
  File "/home/airflow/.local/lib/python3.8/site-packages/airflow/providers/docker/operators/docker.py", line 376, in _run_image
    return self._run_image_with_mounts(self.mounts, add_tmp_variable=False)
  File "/home/airflow/.local/lib/python3.8/site-packages/airflow/providers/docker/operators/docker.py", line 391, in _run_image_with_mounts
    self.container = self.cli.create_container(
  File "/home/airflow/.local/lib/python3.8/site-packages/docker/api/container.py", line 439, in create_container
    return self.create_container_from_config(config, name, platform)
  File "/home/airflow/.local/lib/python3.8/site-packages/docker/api/container.py", line 456, in create_container_from_config
    return self._result(res, True)
  File "/home/airflow/.local/lib/python3.8/site-packages/docker/api/client.py", line 271, in _result
    self._raise_for_status(response)
  File "/home/airflow/.local/lib/python3.8/site-packages/docker/api/client.py", line 267, in _raise_for_status
    raise create_api_error_from_http_exception(e) from e
  File "/home/airflow/.local/lib/python3.8/site-packages/docker/errors.py", line 39, in create_api_error_from_http_exception
    raise cls(e, response=response, explanation=explanation) from e
docker.errors.APIError: 409 Client Error for http+docker://localhost/v1.43/containers/create?name=data_sets: Conflict ("Conflict. The container name "/data_sets" is already in use by container "8d984e03c239954400005629974289d9b69369f297e6b8211e210cf23440ce10". You have to remove (or rename) that container to be able to reuse that name.")
[2024-02-13T10:06:44.832+0000] {taskinstance.py:1138} INFO - Marking task as FAILED. dag_id=deverlop_model, task_id=data_sets, execution_date=20240211T110500, start_date=20240213T100644, end_date=20240213T100644
[2024-02-13T10:06:44.842+0000] {standard_task_runner.py:107} ERROR - Failed to execute job 155 for task data_sets (409 Client Error for http+docker://localhost/v1.43/containers/create?name=data_sets: Conflict ("Conflict. The container name "/data_sets" is already in use by container "8d984e03c239954400005629974289d9b69369f297e6b8211e210cf23440ce10". You have to remove (or rename) that container to be able to reuse that name."); 1214)
[2024-02-13T10:06:44.860+0000] {local_task_job_runner.py:234} INFO - Task exited with return code 1
[2024-02-13T10:06:44.984+0000] {taskinstance.py:3280} INFO - 0 downstream tasks scheduled from follow-on schedule check
