[2024-02-12T14:50:27.726+0000] {taskinstance.py:1956} INFO - Dependencies all met for dep_context=non-requeueable deps ti=<TaskInstance: deverlop_model.data_sets manual__2024-02-12T14:50:26.252402+00:00 [queued]>
[2024-02-12T14:50:27.732+0000] {taskinstance.py:1956} INFO - Dependencies all met for dep_context=requeueable deps ti=<TaskInstance: deverlop_model.data_sets manual__2024-02-12T14:50:26.252402+00:00 [queued]>
[2024-02-12T14:50:27.733+0000] {taskinstance.py:2170} INFO - Starting attempt 1 of 1
[2024-02-12T14:50:27.743+0000] {taskinstance.py:2191} INFO - Executing <Task(DockerOperator): data_sets> on 2024-02-12 14:50:26.252402+00:00
[2024-02-12T14:50:27.748+0000] {standard_task_runner.py:60} INFO - Started process 1056 to run task
[2024-02-12T14:50:27.751+0000] {standard_task_runner.py:87} INFO - Running: ['***', 'tasks', 'run', 'deverlop_model', 'data_sets', 'manual__2024-02-12T14:50:26.252402+00:00', '--job-id', '43', '--raw', '--subdir', 'DAGS_FOLDER/task.py', '--cfg-path', '/tmp/tmpbvuwwuh1']
[2024-02-12T14:50:27.753+0000] {standard_task_runner.py:88} INFO - Job 43: Subtask data_sets
[2024-02-12T14:50:27.791+0000] {task_command.py:423} INFO - Running <TaskInstance: deverlop_model.data_sets manual__2024-02-12T14:50:26.252402+00:00 [running]> on host 5fc906926aab
[2024-02-12T14:50:27.828+0000] {abstractoperator.py:707} ERROR - Exception rendering Jinja template for task 'data_sets', field 'command'. Template: 'bash /task/script.sh'
Traceback (most recent call last):
  File "/home/airflow/.local/lib/python3.8/site-packages/airflow/models/abstractoperator.py", line 699, in _do_render_template_fields
    rendered_content = self.render_template(
  File "/home/airflow/.local/lib/python3.8/site-packages/airflow/template/templater.py", line 171, in render_template
    template = jinja_env.get_template(value)
  File "/home/airflow/.local/lib/python3.8/site-packages/jinja2/environment.py", line 1010, in get_template
    return self._load_template(name, globals)
  File "/home/airflow/.local/lib/python3.8/site-packages/jinja2/environment.py", line 969, in _load_template
    template = self.loader.load(self, name, self.make_globals(globals))
  File "/home/airflow/.local/lib/python3.8/site-packages/jinja2/loaders.py", line 125, in load
    source, filename, uptodate = self.get_source(environment, name)
  File "/home/airflow/.local/lib/python3.8/site-packages/jinja2/loaders.py", line 204, in get_source
    raise TemplateNotFound(template)
jinja2.exceptions.TemplateNotFound: bash /task/script.sh
[2024-02-12T14:50:27.829+0000] {taskinstance.py:2698} ERROR - Task failed with exception
Traceback (most recent call last):
  File "/home/airflow/.local/lib/python3.8/site-packages/airflow/models/taskinstance.py", line 2334, in _run_raw_task
    self._execute_task_with_callbacks(context, test_mode, session=session)
  File "/home/airflow/.local/lib/python3.8/site-packages/airflow/models/taskinstance.py", line 2465, in _execute_task_with_callbacks
    task_orig = self.render_templates(context=context)
  File "/home/airflow/.local/lib/python3.8/site-packages/airflow/models/taskinstance.py", line 2877, in render_templates
    original_task.render_template_fields(context)
  File "/home/airflow/.local/lib/python3.8/site-packages/airflow/models/baseoperator.py", line 1241, in render_template_fields
    self._do_render_template_fields(self, self.template_fields, context, jinja_env, set())
  File "/home/airflow/.local/lib/python3.8/site-packages/airflow/utils/session.py", line 79, in wrapper
    return func(*args, session=session, **kwargs)
  File "/home/airflow/.local/lib/python3.8/site-packages/airflow/models/abstractoperator.py", line 699, in _do_render_template_fields
    rendered_content = self.render_template(
  File "/home/airflow/.local/lib/python3.8/site-packages/airflow/template/templater.py", line 171, in render_template
    template = jinja_env.get_template(value)
  File "/home/airflow/.local/lib/python3.8/site-packages/jinja2/environment.py", line 1010, in get_template
    return self._load_template(name, globals)
  File "/home/airflow/.local/lib/python3.8/site-packages/jinja2/environment.py", line 969, in _load_template
    template = self.loader.load(self, name, self.make_globals(globals))
  File "/home/airflow/.local/lib/python3.8/site-packages/jinja2/loaders.py", line 125, in load
    source, filename, uptodate = self.get_source(environment, name)
  File "/home/airflow/.local/lib/python3.8/site-packages/jinja2/loaders.py", line 204, in get_source
    raise TemplateNotFound(template)
jinja2.exceptions.TemplateNotFound: bash /task/script.sh
[2024-02-12T14:50:27.836+0000] {taskinstance.py:1138} INFO - Marking task as FAILED. dag_id=deverlop_model, task_id=data_sets, execution_date=20240212T145026, start_date=20240212T145027, end_date=20240212T145027
[2024-02-12T14:50:27.845+0000] {standard_task_runner.py:107} ERROR - Failed to execute job 43 for task data_sets (bash /task/script.sh; 1056)
[2024-02-12T14:50:27.884+0000] {local_task_job_runner.py:234} INFO - Task exited with return code 1
[2024-02-12T14:50:27.903+0000] {taskinstance.py:3280} INFO - 0 downstream tasks scheduled from follow-on schedule check
