[2024-02-13T10:00:02.250+0000] {taskinstance.py:1956} INFO - Dependencies all met for dep_context=non-requeueable deps ti=<TaskInstance: example_passing_params_via_test_command.also_run_this scheduled__2024-02-13T09:59:00+00:00 [queued]>
[2024-02-13T10:00:02.256+0000] {taskinstance.py:1956} INFO - Dependencies all met for dep_context=requeueable deps ti=<TaskInstance: example_passing_params_via_test_command.also_run_this scheduled__2024-02-13T09:59:00+00:00 [queued]>
[2024-02-13T10:00:02.257+0000] {taskinstance.py:2170} INFO - Starting attempt 1 of 1
[2024-02-13T10:00:02.268+0000] {taskinstance.py:2191} INFO - Executing <Task(BashOperator): also_run_this> on 2024-02-13 09:59:00+00:00
[2024-02-13T10:00:02.274+0000] {standard_task_runner.py:60} INFO - Started process 643 to run task
[2024-02-13T10:00:02.276+0000] {standard_task_runner.py:87} INFO - Running: ['***', 'tasks', 'run', 'example_passing_params_via_test_command', 'also_run_this', 'scheduled__2024-02-13T09:59:00+00:00', '--job-id', '22', '--raw', '--subdir', '/home/***/.local/lib/python3.8/site-packages/***/example_dags/example_passing_params_via_test_command.py', '--cfg-path', '/tmp/tmpec5dy4lo']
[2024-02-13T10:00:02.279+0000] {standard_task_runner.py:88} INFO - Job 22: Subtask also_run_this
[2024-02-13T10:00:02.321+0000] {task_command.py:423} INFO - Running <TaskInstance: example_passing_params_via_test_command.also_run_this scheduled__2024-02-13T09:59:00+00:00 [running]> on host 292a13d21cb7
[2024-02-13T10:00:02.354+0000] {abstractoperator.py:707} ERROR - Exception rendering Jinja template for task 'also_run_this', field 'env'. Template: {'FOO': '{{ params.foo }}', 'MIFF': '{{ params.miff }}'}
Traceback (most recent call last):
  File "/home/airflow/.local/lib/python3.8/site-packages/airflow/models/abstractoperator.py", line 699, in _do_render_template_fields
    rendered_content = self.render_template(
  File "/home/airflow/.local/lib/python3.8/site-packages/airflow/template/templater.py", line 186, in render_template
    return {k: self.render_template(v, context, jinja_env, oids) for k, v in value.items()}
  File "/home/airflow/.local/lib/python3.8/site-packages/airflow/template/templater.py", line 186, in <dictcomp>
    return {k: self.render_template(v, context, jinja_env, oids) for k, v in value.items()}
  File "/home/airflow/.local/lib/python3.8/site-packages/airflow/template/templater.py", line 174, in render_template
    return self._render(template, context)
  File "/home/airflow/.local/lib/python3.8/site-packages/airflow/models/abstractoperator.py", line 654, in _render
    return super()._render(template, context, dag=dag)
  File "/home/airflow/.local/lib/python3.8/site-packages/airflow/template/templater.py", line 131, in _render
    return render_template_to_string(template, context)
  File "/home/airflow/.local/lib/python3.8/site-packages/airflow/utils/helpers.py", line 289, in render_template_to_string
    return render_template(template, cast(MutableMapping[str, Any], context), native=False)
  File "/home/airflow/.local/lib/python3.8/site-packages/airflow/utils/helpers.py", line 284, in render_template
    return "".join(nodes)
  File "<template>", line 12, in root
  File "/home/airflow/.local/lib/python3.8/site-packages/jinja2/runtime.py", line 852, in _fail_with_undefined_error
    raise self._undefined_exception(self._undefined_message)
jinja2.exceptions.UndefinedError: 'dict object' has no attribute 'foo'
[2024-02-13T10:00:02.355+0000] {taskinstance.py:2698} ERROR - Task failed with exception
Traceback (most recent call last):
  File "/home/airflow/.local/lib/python3.8/site-packages/airflow/models/taskinstance.py", line 2334, in _run_raw_task
    self._execute_task_with_callbacks(context, test_mode, session=session)
  File "/home/airflow/.local/lib/python3.8/site-packages/airflow/models/taskinstance.py", line 2465, in _execute_task_with_callbacks
    task_orig = self.render_templates(context=context)
  File "/home/airflow/.local/lib/python3.8/site-packages/airflow/models/taskinstance.py", line 2877, in render_templates
    original_task.render_template_fields(context)
  File "/home/airflow/.local/lib/python3.8/site-packages/airflow/models/baseoperator.py", line 1241, in render_template_fields
    self._do_render_template_fields(self, self.template_fields, context, jinja_env, set())
  File "/home/airflow/.local/lib/python3.8/site-packages/airflow/utils/session.py", line 79, in wrapper
    return func(*args, session=session, **kwargs)
  File "/home/airflow/.local/lib/python3.8/site-packages/airflow/models/abstractoperator.py", line 699, in _do_render_template_fields
    rendered_content = self.render_template(
  File "/home/airflow/.local/lib/python3.8/site-packages/airflow/template/templater.py", line 186, in render_template
    return {k: self.render_template(v, context, jinja_env, oids) for k, v in value.items()}
  File "/home/airflow/.local/lib/python3.8/site-packages/airflow/template/templater.py", line 186, in <dictcomp>
    return {k: self.render_template(v, context, jinja_env, oids) for k, v in value.items()}
  File "/home/airflow/.local/lib/python3.8/site-packages/airflow/template/templater.py", line 174, in render_template
    return self._render(template, context)
  File "/home/airflow/.local/lib/python3.8/site-packages/airflow/models/abstractoperator.py", line 654, in _render
    return super()._render(template, context, dag=dag)
  File "/home/airflow/.local/lib/python3.8/site-packages/airflow/template/templater.py", line 131, in _render
    return render_template_to_string(template, context)
  File "/home/airflow/.local/lib/python3.8/site-packages/airflow/utils/helpers.py", line 289, in render_template_to_string
    return render_template(template, cast(MutableMapping[str, Any], context), native=False)
  File "/home/airflow/.local/lib/python3.8/site-packages/airflow/utils/helpers.py", line 284, in render_template
    return "".join(nodes)
  File "<template>", line 12, in root
  File "/home/airflow/.local/lib/python3.8/site-packages/jinja2/runtime.py", line 852, in _fail_with_undefined_error
    raise self._undefined_exception(self._undefined_message)
jinja2.exceptions.UndefinedError: 'dict object' has no attribute 'foo'
[2024-02-13T10:00:02.361+0000] {taskinstance.py:1138} INFO - Marking task as FAILED. dag_id=example_passing_params_via_test_command, task_id=also_run_this, execution_date=20240213T095900, start_date=20240213T100002, end_date=20240213T100002
[2024-02-13T10:00:02.371+0000] {standard_task_runner.py:107} ERROR - Failed to execute job 22 for task also_run_this ('dict object' has no attribute 'foo'; 643)
[2024-02-13T10:00:02.409+0000] {local_task_job_runner.py:234} INFO - Task exited with return code 1
[2024-02-13T10:00:02.422+0000] {taskinstance.py:3280} INFO - 0 downstream tasks scheduled from follow-on schedule check
