[2024-02-12T15:15:02.654+0000] {taskinstance.py:1956} INFO - Dependencies all met for dep_context=non-requeueable deps ti=<TaskInstance: deverlop_model.data_sets manual__2024-02-12T15:15:00.979585+00:00 [queued]>
[2024-02-12T15:15:02.661+0000] {taskinstance.py:1956} INFO - Dependencies all met for dep_context=requeueable deps ti=<TaskInstance: deverlop_model.data_sets manual__2024-02-12T15:15:00.979585+00:00 [queued]>
[2024-02-12T15:15:02.662+0000] {taskinstance.py:2170} INFO - Starting attempt 1 of 1
[2024-02-12T15:15:02.676+0000] {taskinstance.py:2191} INFO - Executing <Task(DockerOperator): data_sets> on 2024-02-12 15:15:00.979585+00:00
[2024-02-12T15:15:02.683+0000] {standard_task_runner.py:60} INFO - Started process 1464 to run task
[2024-02-12T15:15:02.686+0000] {standard_task_runner.py:87} INFO - Running: ['***', 'tasks', 'run', 'deverlop_model', 'data_sets', 'manual__2024-02-12T15:15:00.979585+00:00', '--job-id', '56', '--raw', '--subdir', 'DAGS_FOLDER/task.py', '--cfg-path', '/tmp/tmpykkcbu_9']
[2024-02-12T15:15:02.689+0000] {standard_task_runner.py:88} INFO - Job 56: Subtask data_sets
[2024-02-12T15:15:02.736+0000] {task_command.py:423} INFO - Running <TaskInstance: deverlop_model.data_sets manual__2024-02-12T15:15:00.979585+00:00 [running]> on host 5fc906926aab
[2024-02-12T15:15:02.819+0000] {taskinstance.py:2480} INFO - Exporting env vars: AIRFLOW_CTX_DAG_OWNER='rtn' AIRFLOW_CTX_DAG_ID='deverlop_model' AIRFLOW_CTX_TASK_ID='data_sets' AIRFLOW_CTX_EXECUTION_DATE='2024-02-12T15:15:00.979585+00:00' AIRFLOW_CTX_TRY_NUMBER='1' AIRFLOW_CTX_DAG_RUN_ID='manual__2024-02-12T15:15:00.979585+00:00'
[2024-02-12T15:15:02.838+0000] {docker.py:359} INFO - Starting docker container from image python:3.8
[2024-02-12T15:15:03.165+0000] {docker.py:429} INFO - bash: /task/script.sh : No such file or directory
[2024-02-12T15:15:03.597+0000] {taskinstance.py:2698} ERROR - Task failed with exception
Traceback (most recent call last):
  File "/home/airflow/.local/lib/python3.8/site-packages/airflow/models/taskinstance.py", line 433, in _execute_task
    result = execute_callable(context=context, **execute_callable_kwargs)
  File "/home/airflow/.local/lib/python3.8/site-packages/airflow/providers/docker/operators/docker.py", line 502, in execute
    return self._run_image()
  File "/home/airflow/.local/lib/python3.8/site-packages/airflow/providers/docker/operators/docker.py", line 376, in _run_image
    return self._run_image_with_mounts(self.mounts, add_tmp_variable=False)
  File "/home/airflow/.local/lib/python3.8/site-packages/airflow/providers/docker/operators/docker.py", line 437, in _run_image_with_mounts
    raise DockerContainerFailedException(f"Docker container failed: {result!r}", logs=log_lines)
airflow.providers.docker.exceptions.DockerContainerFailedException: Docker container failed: {'StatusCode': 127}
[2024-02-12T15:15:03.600+0000] {taskinstance.py:1138} INFO - Marking task as FAILED. dag_id=deverlop_model, task_id=data_sets, execution_date=20240212T151500, start_date=20240212T151502, end_date=20240212T151503
[2024-02-12T15:15:03.611+0000] {standard_task_runner.py:107} ERROR - Failed to execute job 56 for task data_sets (Docker container failed: {'StatusCode': 127}; 1464)
[2024-02-12T15:15:03.622+0000] {local_task_job_runner.py:234} INFO - Task exited with return code 1
[2024-02-12T15:15:03.641+0000] {taskinstance.py:3280} INFO - 0 downstream tasks scheduled from follow-on schedule check
