[2024-02-14T03:34:28.349+0000] {taskinstance.py:1956} INFO - Dependencies all met for dep_context=non-requeueable deps ti=<TaskInstance: deverlop_model.data_sets scheduled__2024-02-01T00:45:00+00:00 [queued]>
[2024-02-14T03:34:28.412+0000] {taskinstance.py:1956} INFO - Dependencies all met for dep_context=requeueable deps ti=<TaskInstance: deverlop_model.data_sets scheduled__2024-02-01T00:45:00+00:00 [queued]>
[2024-02-14T03:34:28.433+0000] {taskinstance.py:2170} INFO - Starting attempt 1 of 1
[2024-02-14T03:34:28.485+0000] {taskinstance.py:2191} INFO - Executing <Task(DockerOperator): data_sets> on 2024-02-01 00:45:00+00:00
[2024-02-14T03:34:28.514+0000] {standard_task_runner.py:87} INFO - Running: ['***', 'tasks', 'run', 'deverlop_model', 'data_sets', 'scheduled__2024-02-01T00:45:00+00:00', '--job-id', '249', '--raw', '--subdir', 'DAGS_FOLDER/task.py', '--cfg-path', '/tmp/tmpqiso6ybs']
[2024-02-14T03:34:28.522+0000] {standard_task_runner.py:88} INFO - Job 249: Subtask data_sets
[2024-02-14T03:34:28.504+0000] {standard_task_runner.py:60} INFO - Started process 2496 to run task
[2024-02-14T03:34:28.678+0000] {task_command.py:423} INFO - Running <TaskInstance: deverlop_model.data_sets scheduled__2024-02-01T00:45:00+00:00 [running]> on host 6e2ff7d2ffd0
[2024-02-14T03:34:28.807+0000] {taskinstance.py:2480} INFO - Exporting env vars: AIRFLOW_CTX_DAG_OWNER='rtn' AIRFLOW_CTX_DAG_ID='deverlop_model' AIRFLOW_CTX_TASK_ID='data_sets' AIRFLOW_CTX_EXECUTION_DATE='2024-02-01T00:45:00+00:00' AIRFLOW_CTX_TRY_NUMBER='1' AIRFLOW_CTX_DAG_RUN_ID='scheduled__2024-02-01T00:45:00+00:00'
[2024-02-14T03:34:28.877+0000] {docker.py:359} INFO - Starting docker container from image python:3.8
[2024-02-14T03:34:28.910+0000] {taskinstance.py:2698} ERROR - Task failed with exception
Traceback (most recent call last):
  File "/home/airflow/.local/lib/python3.8/site-packages/docker/api/client.py", line 265, in _raise_for_status
    response.raise_for_status()
  File "/home/airflow/.local/lib/python3.8/site-packages/requests/models.py", line 1021, in raise_for_status
    raise HTTPError(http_error_msg, response=self)
requests.exceptions.HTTPError: 409 Client Error: Conflict for url: http+docker://localhost/v1.43/containers/create?name=data_sets

The above exception was the direct cause of the following exception:

Traceback (most recent call last):
  File "/home/airflow/.local/lib/python3.8/site-packages/airflow/models/taskinstance.py", line 433, in _execute_task
    result = execute_callable(context=context, **execute_callable_kwargs)
  File "/home/airflow/.local/lib/python3.8/site-packages/airflow/providers/docker/operators/docker.py", line 502, in execute
    return self._run_image()
  File "/home/airflow/.local/lib/python3.8/site-packages/airflow/providers/docker/operators/docker.py", line 376, in _run_image
    return self._run_image_with_mounts(self.mounts, add_tmp_variable=False)
  File "/home/airflow/.local/lib/python3.8/site-packages/airflow/providers/docker/operators/docker.py", line 391, in _run_image_with_mounts
    self.container = self.cli.create_container(
  File "/home/airflow/.local/lib/python3.8/site-packages/docker/api/container.py", line 439, in create_container
    return self.create_container_from_config(config, name, platform)
  File "/home/airflow/.local/lib/python3.8/site-packages/docker/api/container.py", line 456, in create_container_from_config
    return self._result(res, True)
  File "/home/airflow/.local/lib/python3.8/site-packages/docker/api/client.py", line 271, in _result
    self._raise_for_status(response)
  File "/home/airflow/.local/lib/python3.8/site-packages/docker/api/client.py", line 267, in _raise_for_status
    raise create_api_error_from_http_exception(e) from e
  File "/home/airflow/.local/lib/python3.8/site-packages/docker/errors.py", line 39, in create_api_error_from_http_exception
    raise cls(e, response=response, explanation=explanation) from e
docker.errors.APIError: 409 Client Error for http+docker://localhost/v1.43/containers/create?name=data_sets: Conflict ("Conflict. The container name "/data_sets" is already in use by container "ac3379fb148357dc9ddee1b0faa3062cdb812b9639673ca1db4737015ab26c83". You have to remove (or rename) that container to be able to reuse that name.")
[2024-02-14T03:34:28.928+0000] {taskinstance.py:1138} INFO - Marking task as FAILED. dag_id=deverlop_model, task_id=data_sets, execution_date=20240201T004500, start_date=20240214T033428, end_date=20240214T033428
[2024-02-14T03:34:28.949+0000] {standard_task_runner.py:107} ERROR - Failed to execute job 249 for task data_sets (409 Client Error for http+docker://localhost/v1.43/containers/create?name=data_sets: Conflict ("Conflict. The container name "/data_sets" is already in use by container "ac3379fb148357dc9ddee1b0faa3062cdb812b9639673ca1db4737015ab26c83". You have to remove (or rename) that container to be able to reuse that name."); 2496)
[2024-02-14T03:34:28.968+0000] {local_task_job_runner.py:234} INFO - Task exited with return code 1
[2024-02-14T03:34:28.995+0000] {taskinstance.py:3280} INFO - 0 downstream tasks scheduled from follow-on schedule check
[2024-02-14T03:38:03.479+0000] {taskinstance.py:1956} INFO - Dependencies all met for dep_context=non-requeueable deps ti=<TaskInstance: deverlop_model.data_sets scheduled__2024-02-01T00:45:00+00:00 [queued]>
[2024-02-14T03:38:03.503+0000] {taskinstance.py:1956} INFO - Dependencies all met for dep_context=requeueable deps ti=<TaskInstance: deverlop_model.data_sets scheduled__2024-02-01T00:45:00+00:00 [queued]>
[2024-02-14T03:38:03.504+0000] {taskinstance.py:2170} INFO - Starting attempt 1 of 1
[2024-02-14T03:38:03.528+0000] {taskinstance.py:2191} INFO - Executing <Task(DockerOperator): data_sets> on 2024-02-01 00:45:00+00:00
[2024-02-14T03:38:03.539+0000] {standard_task_runner.py:60} INFO - Started process 2816 to run task
[2024-02-14T03:38:03.543+0000] {standard_task_runner.py:87} INFO - Running: ['***', 'tasks', 'run', 'deverlop_model', 'data_sets', 'scheduled__2024-02-01T00:45:00+00:00', '--job-id', '323', '--raw', '--subdir', 'DAGS_FOLDER/task.py', '--cfg-path', '/tmp/tmptrd62s2b']
[2024-02-14T03:38:03.554+0000] {standard_task_runner.py:88} INFO - Job 323: Subtask data_sets
[2024-02-14T03:38:03.656+0000] {task_command.py:423} INFO - Running <TaskInstance: deverlop_model.data_sets scheduled__2024-02-01T00:45:00+00:00 [running]> on host 6e2ff7d2ffd0
[2024-02-14T03:38:03.769+0000] {taskinstance.py:2480} INFO - Exporting env vars: AIRFLOW_CTX_DAG_OWNER='rtn' AIRFLOW_CTX_DAG_ID='deverlop_model' AIRFLOW_CTX_TASK_ID='data_sets' AIRFLOW_CTX_EXECUTION_DATE='2024-02-01T00:45:00+00:00' AIRFLOW_CTX_TRY_NUMBER='1' AIRFLOW_CTX_DAG_RUN_ID='scheduled__2024-02-01T00:45:00+00:00'
[2024-02-14T03:38:03.797+0000] {docker.py:359} INFO - Starting docker container from image python:3.8
[2024-02-14T03:38:03.805+0000] {taskinstance.py:2698} ERROR - Task failed with exception
Traceback (most recent call last):
  File "/home/airflow/.local/lib/python3.8/site-packages/docker/api/client.py", line 265, in _raise_for_status
    response.raise_for_status()
  File "/home/airflow/.local/lib/python3.8/site-packages/requests/models.py", line 1021, in raise_for_status
    raise HTTPError(http_error_msg, response=self)
requests.exceptions.HTTPError: 409 Client Error: Conflict for url: http+docker://localhost/v1.43/containers/create?name=data_sets

The above exception was the direct cause of the following exception:

Traceback (most recent call last):
  File "/home/airflow/.local/lib/python3.8/site-packages/airflow/models/taskinstance.py", line 433, in _execute_task
    result = execute_callable(context=context, **execute_callable_kwargs)
  File "/home/airflow/.local/lib/python3.8/site-packages/airflow/providers/docker/operators/docker.py", line 502, in execute
    return self._run_image()
  File "/home/airflow/.local/lib/python3.8/site-packages/airflow/providers/docker/operators/docker.py", line 376, in _run_image
    return self._run_image_with_mounts(self.mounts, add_tmp_variable=False)
  File "/home/airflow/.local/lib/python3.8/site-packages/airflow/providers/docker/operators/docker.py", line 391, in _run_image_with_mounts
    self.container = self.cli.create_container(
  File "/home/airflow/.local/lib/python3.8/site-packages/docker/api/container.py", line 439, in create_container
    return self.create_container_from_config(config, name, platform)
  File "/home/airflow/.local/lib/python3.8/site-packages/docker/api/container.py", line 456, in create_container_from_config
    return self._result(res, True)
  File "/home/airflow/.local/lib/python3.8/site-packages/docker/api/client.py", line 271, in _result
    self._raise_for_status(response)
  File "/home/airflow/.local/lib/python3.8/site-packages/docker/api/client.py", line 267, in _raise_for_status
    raise create_api_error_from_http_exception(e) from e
  File "/home/airflow/.local/lib/python3.8/site-packages/docker/errors.py", line 39, in create_api_error_from_http_exception
    raise cls(e, response=response, explanation=explanation) from e
docker.errors.APIError: 409 Client Error for http+docker://localhost/v1.43/containers/create?name=data_sets: Conflict ("Conflict. The container name "/data_sets" is already in use by container "7302939a532eeb4fbe33ede163277e207e5dec00731706b35a5fe6bffd47e265". You have to remove (or rename) that container to be able to reuse that name.")
[2024-02-14T03:38:03.818+0000] {taskinstance.py:1138} INFO - Marking task as FAILED. dag_id=deverlop_model, task_id=data_sets, execution_date=20240201T004500, start_date=20240214T033803, end_date=20240214T033803
[2024-02-14T03:38:03.843+0000] {standard_task_runner.py:107} ERROR - Failed to execute job 323 for task data_sets (409 Client Error for http+docker://localhost/v1.43/containers/create?name=data_sets: Conflict ("Conflict. The container name "/data_sets" is already in use by container "7302939a532eeb4fbe33ede163277e207e5dec00731706b35a5fe6bffd47e265". You have to remove (or rename) that container to be able to reuse that name."); 2816)
[2024-02-14T03:38:03.896+0000] {local_task_job_runner.py:234} INFO - Task exited with return code 1
[2024-02-14T03:38:03.950+0000] {taskinstance.py:3280} INFO - 0 downstream tasks scheduled from follow-on schedule check
[2024-02-14T03:39:29.284+0000] {taskinstance.py:1956} INFO - Dependencies all met for dep_context=non-requeueable deps ti=<TaskInstance: deverlop_model.data_sets scheduled__2024-02-01T00:45:00+00:00 [queued]>
[2024-02-14T03:39:29.302+0000] {taskinstance.py:1956} INFO - Dependencies all met for dep_context=requeueable deps ti=<TaskInstance: deverlop_model.data_sets scheduled__2024-02-01T00:45:00+00:00 [queued]>
[2024-02-14T03:39:29.304+0000] {taskinstance.py:2170} INFO - Starting attempt 1 of 1
[2024-02-14T03:39:29.330+0000] {taskinstance.py:2191} INFO - Executing <Task(DockerOperator): data_sets> on 2024-02-01 00:45:00+00:00
[2024-02-14T03:39:29.343+0000] {standard_task_runner.py:60} INFO - Started process 3024 to run task
[2024-02-14T03:39:29.347+0000] {standard_task_runner.py:87} INFO - Running: ['***', 'tasks', 'run', 'deverlop_model', 'data_sets', 'scheduled__2024-02-01T00:45:00+00:00', '--job-id', '379', '--raw', '--subdir', 'DAGS_FOLDER/task.py', '--cfg-path', '/tmp/tmp8p6kdr4z']
[2024-02-14T03:39:29.351+0000] {standard_task_runner.py:88} INFO - Job 379: Subtask data_sets
[2024-02-14T03:39:29.426+0000] {task_command.py:423} INFO - Running <TaskInstance: deverlop_model.data_sets scheduled__2024-02-01T00:45:00+00:00 [running]> on host 6e2ff7d2ffd0
[2024-02-14T03:39:29.541+0000] {taskinstance.py:2480} INFO - Exporting env vars: AIRFLOW_CTX_DAG_OWNER='rtn' AIRFLOW_CTX_DAG_ID='deverlop_model' AIRFLOW_CTX_TASK_ID='data_sets' AIRFLOW_CTX_EXECUTION_DATE='2024-02-01T00:45:00+00:00' AIRFLOW_CTX_TRY_NUMBER='1' AIRFLOW_CTX_DAG_RUN_ID='scheduled__2024-02-01T00:45:00+00:00'
[2024-02-14T03:39:29.572+0000] {docker.py:359} INFO - Starting docker container from image python:3.8
[2024-02-14T03:39:29.581+0000] {taskinstance.py:2698} ERROR - Task failed with exception
Traceback (most recent call last):
  File "/home/airflow/.local/lib/python3.8/site-packages/docker/api/client.py", line 265, in _raise_for_status
    response.raise_for_status()
  File "/home/airflow/.local/lib/python3.8/site-packages/requests/models.py", line 1021, in raise_for_status
    raise HTTPError(http_error_msg, response=self)
requests.exceptions.HTTPError: 409 Client Error: Conflict for url: http+docker://localhost/v1.43/containers/create?name=data_sets

The above exception was the direct cause of the following exception:

Traceback (most recent call last):
  File "/home/airflow/.local/lib/python3.8/site-packages/airflow/models/taskinstance.py", line 433, in _execute_task
    result = execute_callable(context=context, **execute_callable_kwargs)
  File "/home/airflow/.local/lib/python3.8/site-packages/airflow/providers/docker/operators/docker.py", line 502, in execute
    return self._run_image()
  File "/home/airflow/.local/lib/python3.8/site-packages/airflow/providers/docker/operators/docker.py", line 376, in _run_image
    return self._run_image_with_mounts(self.mounts, add_tmp_variable=False)
  File "/home/airflow/.local/lib/python3.8/site-packages/airflow/providers/docker/operators/docker.py", line 391, in _run_image_with_mounts
    self.container = self.cli.create_container(
  File "/home/airflow/.local/lib/python3.8/site-packages/docker/api/container.py", line 439, in create_container
    return self.create_container_from_config(config, name, platform)
  File "/home/airflow/.local/lib/python3.8/site-packages/docker/api/container.py", line 456, in create_container_from_config
    return self._result(res, True)
  File "/home/airflow/.local/lib/python3.8/site-packages/docker/api/client.py", line 271, in _result
    self._raise_for_status(response)
  File "/home/airflow/.local/lib/python3.8/site-packages/docker/api/client.py", line 267, in _raise_for_status
    raise create_api_error_from_http_exception(e) from e
  File "/home/airflow/.local/lib/python3.8/site-packages/docker/errors.py", line 39, in create_api_error_from_http_exception
    raise cls(e, response=response, explanation=explanation) from e
docker.errors.APIError: 409 Client Error for http+docker://localhost/v1.43/containers/create?name=data_sets: Conflict ("Conflict. The container name "/data_sets" is already in use by container "33af6d28a2541e7971c878b23be5daa60420e9e541b4fa61cf521dbd9db46c50". You have to remove (or rename) that container to be able to reuse that name.")
[2024-02-14T03:39:29.597+0000] {taskinstance.py:1138} INFO - Marking task as FAILED. dag_id=deverlop_model, task_id=data_sets, execution_date=20240201T004500, start_date=20240214T033929, end_date=20240214T033929
[2024-02-14T03:39:29.616+0000] {standard_task_runner.py:107} ERROR - Failed to execute job 379 for task data_sets (409 Client Error for http+docker://localhost/v1.43/containers/create?name=data_sets: Conflict ("Conflict. The container name "/data_sets" is already in use by container "33af6d28a2541e7971c878b23be5daa60420e9e541b4fa61cf521dbd9db46c50". You have to remove (or rename) that container to be able to reuse that name."); 3024)
[2024-02-14T03:39:29.642+0000] {local_task_job_runner.py:234} INFO - Task exited with return code 1
[2024-02-14T03:39:29.799+0000] {taskinstance.py:3280} INFO - 0 downstream tasks scheduled from follow-on schedule check
