[2024-02-14T03:34:42.106+0000] {taskinstance.py:1956} INFO - Dependencies all met for dep_context=non-requeueable deps ti=<TaskInstance: deverlop_model.data_sets scheduled__2024-02-01T02:00:00+00:00 [queued]>
[2024-02-14T03:34:42.124+0000] {taskinstance.py:1956} INFO - Dependencies all met for dep_context=requeueable deps ti=<TaskInstance: deverlop_model.data_sets scheduled__2024-02-01T02:00:00+00:00 [queued]>
[2024-02-14T03:34:42.125+0000] {taskinstance.py:2170} INFO - Starting attempt 1 of 1
[2024-02-14T03:34:42.162+0000] {taskinstance.py:2191} INFO - Executing <Task(DockerOperator): data_sets> on 2024-02-01 02:00:00+00:00
[2024-02-14T03:34:42.181+0000] {standard_task_runner.py:60} INFO - Started process 2606 to run task
[2024-02-14T03:34:42.191+0000] {standard_task_runner.py:87} INFO - Running: ['***', 'tasks', 'run', 'deverlop_model', 'data_sets', 'scheduled__2024-02-01T02:00:00+00:00', '--job-id', '279', '--raw', '--subdir', 'DAGS_FOLDER/task.py', '--cfg-path', '/tmp/tmpbdoqsfi4']
[2024-02-14T03:34:42.199+0000] {standard_task_runner.py:88} INFO - Job 279: Subtask data_sets
[2024-02-14T03:34:42.308+0000] {task_command.py:423} INFO - Running <TaskInstance: deverlop_model.data_sets scheduled__2024-02-01T02:00:00+00:00 [running]> on host 6e2ff7d2ffd0
[2024-02-14T03:34:42.466+0000] {taskinstance.py:2480} INFO - Exporting env vars: AIRFLOW_CTX_DAG_OWNER='rtn' AIRFLOW_CTX_DAG_ID='deverlop_model' AIRFLOW_CTX_TASK_ID='data_sets' AIRFLOW_CTX_EXECUTION_DATE='2024-02-01T02:00:00+00:00' AIRFLOW_CTX_TRY_NUMBER='1' AIRFLOW_CTX_DAG_RUN_ID='scheduled__2024-02-01T02:00:00+00:00'
[2024-02-14T03:34:42.494+0000] {docker.py:359} INFO - Starting docker container from image python:3.8
[2024-02-14T03:34:42.501+0000] {taskinstance.py:2698} ERROR - Task failed with exception
Traceback (most recent call last):
  File "/home/airflow/.local/lib/python3.8/site-packages/docker/api/client.py", line 265, in _raise_for_status
    response.raise_for_status()
  File "/home/airflow/.local/lib/python3.8/site-packages/requests/models.py", line 1021, in raise_for_status
    raise HTTPError(http_error_msg, response=self)
requests.exceptions.HTTPError: 409 Client Error: Conflict for url: http+docker://localhost/v1.43/containers/create?name=data_sets

The above exception was the direct cause of the following exception:

Traceback (most recent call last):
  File "/home/airflow/.local/lib/python3.8/site-packages/airflow/models/taskinstance.py", line 433, in _execute_task
    result = execute_callable(context=context, **execute_callable_kwargs)
  File "/home/airflow/.local/lib/python3.8/site-packages/airflow/providers/docker/operators/docker.py", line 502, in execute
    return self._run_image()
  File "/home/airflow/.local/lib/python3.8/site-packages/airflow/providers/docker/operators/docker.py", line 376, in _run_image
    return self._run_image_with_mounts(self.mounts, add_tmp_variable=False)
  File "/home/airflow/.local/lib/python3.8/site-packages/airflow/providers/docker/operators/docker.py", line 391, in _run_image_with_mounts
    self.container = self.cli.create_container(
  File "/home/airflow/.local/lib/python3.8/site-packages/docker/api/container.py", line 439, in create_container
    return self.create_container_from_config(config, name, platform)
  File "/home/airflow/.local/lib/python3.8/site-packages/docker/api/container.py", line 456, in create_container_from_config
    return self._result(res, True)
  File "/home/airflow/.local/lib/python3.8/site-packages/docker/api/client.py", line 271, in _result
    self._raise_for_status(response)
  File "/home/airflow/.local/lib/python3.8/site-packages/docker/api/client.py", line 267, in _raise_for_status
    raise create_api_error_from_http_exception(e) from e
  File "/home/airflow/.local/lib/python3.8/site-packages/docker/errors.py", line 39, in create_api_error_from_http_exception
    raise cls(e, response=response, explanation=explanation) from e
docker.errors.APIError: 409 Client Error for http+docker://localhost/v1.43/containers/create?name=data_sets: Conflict ("Conflict. The container name "/data_sets" is already in use by container "313554b20f024cf940e8f5acfb7aa90c2cabaa7c4d14cc50436e986be64f1ff6". You have to remove (or rename) that container to be able to reuse that name.")
[2024-02-14T03:34:42.515+0000] {taskinstance.py:1138} INFO - Marking task as FAILED. dag_id=deverlop_model, task_id=data_sets, execution_date=20240201T020000, start_date=20240214T033442, end_date=20240214T033442
[2024-02-14T03:34:42.533+0000] {standard_task_runner.py:107} ERROR - Failed to execute job 279 for task data_sets (409 Client Error for http+docker://localhost/v1.43/containers/create?name=data_sets: Conflict ("Conflict. The container name "/data_sets" is already in use by container "313554b20f024cf940e8f5acfb7aa90c2cabaa7c4d14cc50436e986be64f1ff6". You have to remove (or rename) that container to be able to reuse that name."); 2606)
[2024-02-14T03:34:42.556+0000] {local_task_job_runner.py:234} INFO - Task exited with return code 1
[2024-02-14T03:34:42.589+0000] {taskinstance.py:3280} INFO - 0 downstream tasks scheduled from follow-on schedule check
[2024-02-14T03:39:41.723+0000] {taskinstance.py:1956} INFO - Dependencies all met for dep_context=non-requeueable deps ti=<TaskInstance: deverlop_model.data_sets scheduled__2024-02-01T02:00:00+00:00 [queued]>
[2024-02-14T03:39:41.736+0000] {taskinstance.py:1956} INFO - Dependencies all met for dep_context=requeueable deps ti=<TaskInstance: deverlop_model.data_sets scheduled__2024-02-01T02:00:00+00:00 [queued]>
[2024-02-14T03:39:41.737+0000] {taskinstance.py:2170} INFO - Starting attempt 1 of 1
[2024-02-14T03:39:41.753+0000] {taskinstance.py:2191} INFO - Executing <Task(DockerOperator): data_sets> on 2024-02-01 02:00:00+00:00
[2024-02-14T03:39:41.775+0000] {standard_task_runner.py:60} INFO - Started process 3135 to run task
[2024-02-14T03:39:41.779+0000] {standard_task_runner.py:87} INFO - Running: ['***', 'tasks', 'run', 'deverlop_model', 'data_sets', 'scheduled__2024-02-01T02:00:00+00:00', '--job-id', '408', '--raw', '--subdir', 'DAGS_FOLDER/task.py', '--cfg-path', '/tmp/tmpdbvbz0e7']
[2024-02-14T03:39:41.782+0000] {standard_task_runner.py:88} INFO - Job 408: Subtask data_sets
[2024-02-14T03:39:41.846+0000] {task_command.py:423} INFO - Running <TaskInstance: deverlop_model.data_sets scheduled__2024-02-01T02:00:00+00:00 [running]> on host 6e2ff7d2ffd0
[2024-02-14T03:39:41.973+0000] {taskinstance.py:2480} INFO - Exporting env vars: AIRFLOW_CTX_DAG_OWNER='rtn' AIRFLOW_CTX_DAG_ID='deverlop_model' AIRFLOW_CTX_TASK_ID='data_sets' AIRFLOW_CTX_EXECUTION_DATE='2024-02-01T02:00:00+00:00' AIRFLOW_CTX_TRY_NUMBER='1' AIRFLOW_CTX_DAG_RUN_ID='scheduled__2024-02-01T02:00:00+00:00'
[2024-02-14T03:39:42.013+0000] {docker.py:359} INFO - Starting docker container from image python:3.8
[2024-02-14T03:39:42.024+0000] {taskinstance.py:2698} ERROR - Task failed with exception
Traceback (most recent call last):
  File "/home/airflow/.local/lib/python3.8/site-packages/docker/api/client.py", line 265, in _raise_for_status
    response.raise_for_status()
  File "/home/airflow/.local/lib/python3.8/site-packages/requests/models.py", line 1021, in raise_for_status
    raise HTTPError(http_error_msg, response=self)
requests.exceptions.HTTPError: 409 Client Error: Conflict for url: http+docker://localhost/v1.43/containers/create?name=data_sets

The above exception was the direct cause of the following exception:

Traceback (most recent call last):
  File "/home/airflow/.local/lib/python3.8/site-packages/airflow/models/taskinstance.py", line 433, in _execute_task
    result = execute_callable(context=context, **execute_callable_kwargs)
  File "/home/airflow/.local/lib/python3.8/site-packages/airflow/providers/docker/operators/docker.py", line 502, in execute
    return self._run_image()
  File "/home/airflow/.local/lib/python3.8/site-packages/airflow/providers/docker/operators/docker.py", line 376, in _run_image
    return self._run_image_with_mounts(self.mounts, add_tmp_variable=False)
  File "/home/airflow/.local/lib/python3.8/site-packages/airflow/providers/docker/operators/docker.py", line 391, in _run_image_with_mounts
    self.container = self.cli.create_container(
  File "/home/airflow/.local/lib/python3.8/site-packages/docker/api/container.py", line 439, in create_container
    return self.create_container_from_config(config, name, platform)
  File "/home/airflow/.local/lib/python3.8/site-packages/docker/api/container.py", line 456, in create_container_from_config
    return self._result(res, True)
  File "/home/airflow/.local/lib/python3.8/site-packages/docker/api/client.py", line 271, in _result
    self._raise_for_status(response)
  File "/home/airflow/.local/lib/python3.8/site-packages/docker/api/client.py", line 267, in _raise_for_status
    raise create_api_error_from_http_exception(e) from e
  File "/home/airflow/.local/lib/python3.8/site-packages/docker/errors.py", line 39, in create_api_error_from_http_exception
    raise cls(e, response=response, explanation=explanation) from e
docker.errors.APIError: 409 Client Error for http+docker://localhost/v1.43/containers/create?name=data_sets: Conflict ("Conflict. The container name "/data_sets" is already in use by container "f4ba41b19d7be63924e56800d2dbda792af1e47be818fd184823fa28f93782b2". You have to remove (or rename) that container to be able to reuse that name.")
[2024-02-14T03:39:42.041+0000] {taskinstance.py:1138} INFO - Marking task as FAILED. dag_id=deverlop_model, task_id=data_sets, execution_date=20240201T020000, start_date=20240214T033941, end_date=20240214T033942
[2024-02-14T03:39:42.063+0000] {standard_task_runner.py:107} ERROR - Failed to execute job 408 for task data_sets (409 Client Error for http+docker://localhost/v1.43/containers/create?name=data_sets: Conflict ("Conflict. The container name "/data_sets" is already in use by container "f4ba41b19d7be63924e56800d2dbda792af1e47be818fd184823fa28f93782b2". You have to remove (or rename) that container to be able to reuse that name."); 3135)
[2024-02-14T03:39:42.119+0000] {local_task_job_runner.py:234} INFO - Task exited with return code 1
[2024-02-14T03:39:42.216+0000] {taskinstance.py:3280} INFO - 0 downstream tasks scheduled from follow-on schedule check
