[2024-02-13T06:31:18.382+0000] {taskinstance.py:1956} INFO - Dependencies all met for dep_context=non-requeueable deps ti=<TaskInstance: deverlop_model.prepare_data_set manual__2024-02-13T06:30:36.351627+00:00 [queued]>
[2024-02-13T06:31:18.390+0000] {taskinstance.py:1956} INFO - Dependencies all met for dep_context=requeueable deps ti=<TaskInstance: deverlop_model.prepare_data_set manual__2024-02-13T06:30:36.351627+00:00 [queued]>
[2024-02-13T06:31:18.391+0000] {taskinstance.py:2170} INFO - Starting attempt 1 of 1
[2024-02-13T06:31:18.402+0000] {taskinstance.py:2191} INFO - Executing <Task(DockerOperator): prepare_data_set> on 2024-02-13 06:30:36.351627+00:00
[2024-02-13T06:31:18.409+0000] {standard_task_runner.py:60} INFO - Started process 85 to run task
[2024-02-13T06:31:18.411+0000] {standard_task_runner.py:87} INFO - Running: ['***', 'tasks', 'run', 'deverlop_model', 'prepare_data_set', 'manual__2024-02-13T06:30:36.351627+00:00', '--job-id', '4', '--raw', '--subdir', 'DAGS_FOLDER/task.py', '--cfg-path', '/tmp/tmpq2298ovu']
[2024-02-13T06:31:18.414+0000] {standard_task_runner.py:88} INFO - Job 4: Subtask prepare_data_set
[2024-02-13T06:31:18.456+0000] {task_command.py:423} INFO - Running <TaskInstance: deverlop_model.prepare_data_set manual__2024-02-13T06:30:36.351627+00:00 [running]> on host c77919780a82
[2024-02-13T06:31:18.518+0000] {taskinstance.py:2480} INFO - Exporting env vars: AIRFLOW_CTX_DAG_OWNER='rtn' AIRFLOW_CTX_DAG_ID='deverlop_model' AIRFLOW_CTX_TASK_ID='prepare_data_set' AIRFLOW_CTX_EXECUTION_DATE='2024-02-13T06:30:36.351627+00:00' AIRFLOW_CTX_TRY_NUMBER='1' AIRFLOW_CTX_DAG_RUN_ID='manual__2024-02-13T06:30:36.351627+00:00'
[2024-02-13T06:31:18.538+0000] {docker.py:359} INFO - Starting docker container from image python:3.8
[2024-02-13T06:31:20.130+0000] {docker.py:429} INFO - WARNING: Running pip as the 'root' user can result in broken permissions and conflicting behaviour with the system package manager. It is recommended to use a virtual environment instead: https://pip.pypa.io/warnings/venv
[2024-02-13T06:31:20.310+0000] {docker.py:429} INFO - [notice] A new release of pip is available: 23.0.1 -> 24.0
[notice] To update, run: pip install --upgrade pip
[2024-02-13T06:31:25.451+0000] {docker.py:429} INFO - READ DATA :  DataSets : 2024-02-13 06:31:16.345978  timestamp :  2024-02-13 06:31:25.443582
[2024-02-13T06:31:25.802+0000] {taskinstance.py:1138} INFO - Marking task as SUCCESS. dag_id=deverlop_model, task_id=prepare_data_set, execution_date=20240213T063036, start_date=20240213T063118, end_date=20240213T063125
[2024-02-13T06:31:25.854+0000] {local_task_job_runner.py:234} INFO - Task exited with return code 0
[2024-02-13T06:31:25.867+0000] {taskinstance.py:3280} INFO - 0 downstream tasks scheduled from follow-on schedule check
