[2024-02-14T02:07:49.693+0000] {taskinstance.py:1956} INFO - Dependencies all met for dep_context=non-requeueable deps ti=<TaskInstance: deverlop_model.prepare_data_set scheduled__2024-01-01T02:55:00+00:00 [queued]>
[2024-02-14T02:07:49.704+0000] {taskinstance.py:1956} INFO - Dependencies all met for dep_context=requeueable deps ti=<TaskInstance: deverlop_model.prepare_data_set scheduled__2024-01-01T02:55:00+00:00 [queued]>
[2024-02-14T02:07:49.705+0000] {taskinstance.py:2170} INFO - Starting attempt 1 of 1
[2024-02-14T02:07:49.720+0000] {taskinstance.py:2191} INFO - Executing <Task(DockerOperator): prepare_data_set> on 2024-01-01 02:55:00+00:00
[2024-02-14T02:07:49.729+0000] {standard_task_runner.py:60} INFO - Started process 611 to run task
[2024-02-14T02:07:49.732+0000] {standard_task_runner.py:87} INFO - Running: ['***', 'tasks', 'run', 'deverlop_model', 'prepare_data_set', 'scheduled__2024-01-01T02:55:00+00:00', '--job-id', '91', '--raw', '--subdir', 'DAGS_FOLDER/task.py', '--cfg-path', '/tmp/tmpduvodxmt']
[2024-02-14T02:07:49.734+0000] {standard_task_runner.py:88} INFO - Job 91: Subtask prepare_data_set
[2024-02-14T02:07:49.783+0000] {task_command.py:423} INFO - Running <TaskInstance: deverlop_model.prepare_data_set scheduled__2024-01-01T02:55:00+00:00 [running]> on host 6e2ff7d2ffd0
[2024-02-14T02:07:49.860+0000] {taskinstance.py:2480} INFO - Exporting env vars: AIRFLOW_CTX_DAG_OWNER='rtn' AIRFLOW_CTX_DAG_ID='deverlop_model' AIRFLOW_CTX_TASK_ID='prepare_data_set' AIRFLOW_CTX_EXECUTION_DATE='2024-01-01T02:55:00+00:00' AIRFLOW_CTX_TRY_NUMBER='1' AIRFLOW_CTX_DAG_RUN_ID='scheduled__2024-01-01T02:55:00+00:00'
[2024-02-14T02:07:49.877+0000] {docker.py:359} INFO - Starting docker container from image python:3.8
[2024-02-14T02:07:51.746+0000] {docker.py:429} INFO - WARNING: Running pip as the 'root' user can result in broken permissions and conflicting behaviour with the system package manager. It is recommended to use a virtual environment instead: https://pip.pypa.io/warnings/venv
[2024-02-14T02:07:51.909+0000] {docker.py:429} INFO - [notice] A new release of pip is available: 23.0.1 -> 24.0
[notice] To update, run: pip install --upgrade pip
[2024-02-14T02:07:56.998+0000] {docker.py:429} INFO - READ DATA :  DataSets : 2024-02-14 02:07:47.320715  timestamp :  2024-02-14 02:07:56.995878
[2024-02-14T02:07:57.405+0000] {taskinstance.py:1138} INFO - Marking task as SUCCESS. dag_id=deverlop_model, task_id=prepare_data_set, execution_date=20240101T025500, start_date=20240214T020749, end_date=20240214T020757
[2024-02-14T02:07:57.449+0000] {local_task_job_runner.py:234} INFO - Task exited with return code 0
[2024-02-14T02:07:57.464+0000] {taskinstance.py:3280} INFO - 2 downstream tasks scheduled from follow-on schedule check
