[2024-02-14T03:34:32.490+0000] {taskinstance.py:1956} INFO - Dependencies all met for dep_context=non-requeueable deps ti=<TaskInstance: deverlop_model.data_sets scheduled__2024-02-01T01:15:00+00:00 [queued]>
[2024-02-14T03:34:32.499+0000] {taskinstance.py:1956} INFO - Dependencies all met for dep_context=requeueable deps ti=<TaskInstance: deverlop_model.data_sets scheduled__2024-02-01T01:15:00+00:00 [queued]>
[2024-02-14T03:34:32.500+0000] {taskinstance.py:2170} INFO - Starting attempt 1 of 1
[2024-02-14T03:34:32.513+0000] {taskinstance.py:2191} INFO - Executing <Task(DockerOperator): data_sets> on 2024-02-01 01:15:00+00:00
[2024-02-14T03:34:32.522+0000] {standard_task_runner.py:60} INFO - Started process 2514 to run task
[2024-02-14T03:34:32.525+0000] {standard_task_runner.py:87} INFO - Running: ['***', 'tasks', 'run', 'deverlop_model', 'data_sets', 'scheduled__2024-02-01T01:15:00+00:00', '--job-id', '255', '--raw', '--subdir', 'DAGS_FOLDER/task.py', '--cfg-path', '/tmp/tmpqn74ici4']
[2024-02-14T03:34:32.528+0000] {standard_task_runner.py:88} INFO - Job 255: Subtask data_sets
[2024-02-14T03:34:32.580+0000] {task_command.py:423} INFO - Running <TaskInstance: deverlop_model.data_sets scheduled__2024-02-01T01:15:00+00:00 [running]> on host 6e2ff7d2ffd0
[2024-02-14T03:34:32.656+0000] {taskinstance.py:2480} INFO - Exporting env vars: AIRFLOW_CTX_DAG_OWNER='rtn' AIRFLOW_CTX_DAG_ID='deverlop_model' AIRFLOW_CTX_TASK_ID='data_sets' AIRFLOW_CTX_EXECUTION_DATE='2024-02-01T01:15:00+00:00' AIRFLOW_CTX_TRY_NUMBER='1' AIRFLOW_CTX_DAG_RUN_ID='scheduled__2024-02-01T01:15:00+00:00'
[2024-02-14T03:34:32.675+0000] {docker.py:359} INFO - Starting docker container from image python:3.8
[2024-02-14T03:34:32.680+0000] {taskinstance.py:2698} ERROR - Task failed with exception
Traceback (most recent call last):
  File "/home/airflow/.local/lib/python3.8/site-packages/docker/api/client.py", line 265, in _raise_for_status
    response.raise_for_status()
  File "/home/airflow/.local/lib/python3.8/site-packages/requests/models.py", line 1021, in raise_for_status
    raise HTTPError(http_error_msg, response=self)
requests.exceptions.HTTPError: 409 Client Error: Conflict for url: http+docker://localhost/v1.43/containers/create?name=data_sets

The above exception was the direct cause of the following exception:

Traceback (most recent call last):
  File "/home/airflow/.local/lib/python3.8/site-packages/airflow/models/taskinstance.py", line 433, in _execute_task
    result = execute_callable(context=context, **execute_callable_kwargs)
  File "/home/airflow/.local/lib/python3.8/site-packages/airflow/providers/docker/operators/docker.py", line 502, in execute
    return self._run_image()
  File "/home/airflow/.local/lib/python3.8/site-packages/airflow/providers/docker/operators/docker.py", line 376, in _run_image
    return self._run_image_with_mounts(self.mounts, add_tmp_variable=False)
  File "/home/airflow/.local/lib/python3.8/site-packages/airflow/providers/docker/operators/docker.py", line 391, in _run_image_with_mounts
    self.container = self.cli.create_container(
  File "/home/airflow/.local/lib/python3.8/site-packages/docker/api/container.py", line 439, in create_container
    return self.create_container_from_config(config, name, platform)
  File "/home/airflow/.local/lib/python3.8/site-packages/docker/api/container.py", line 456, in create_container_from_config
    return self._result(res, True)
  File "/home/airflow/.local/lib/python3.8/site-packages/docker/api/client.py", line 271, in _result
    self._raise_for_status(response)
  File "/home/airflow/.local/lib/python3.8/site-packages/docker/api/client.py", line 267, in _raise_for_status
    raise create_api_error_from_http_exception(e) from e
  File "/home/airflow/.local/lib/python3.8/site-packages/docker/errors.py", line 39, in create_api_error_from_http_exception
    raise cls(e, response=response, explanation=explanation) from e
docker.errors.APIError: 409 Client Error for http+docker://localhost/v1.43/containers/create?name=data_sets: Conflict ("Conflict. The container name "/data_sets" is already in use by container "ac3379fb148357dc9ddee1b0faa3062cdb812b9639673ca1db4737015ab26c83". You have to remove (or rename) that container to be able to reuse that name.")
[2024-02-14T03:34:32.690+0000] {taskinstance.py:1138} INFO - Marking task as FAILED. dag_id=deverlop_model, task_id=data_sets, execution_date=20240201T011500, start_date=20240214T033432, end_date=20240214T033432
[2024-02-14T03:34:32.702+0000] {standard_task_runner.py:107} ERROR - Failed to execute job 255 for task data_sets (409 Client Error for http+docker://localhost/v1.43/containers/create?name=data_sets: Conflict ("Conflict. The container name "/data_sets" is already in use by container "ac3379fb148357dc9ddee1b0faa3062cdb812b9639673ca1db4737015ab26c83". You have to remove (or rename) that container to be able to reuse that name."); 2514)
[2024-02-14T03:34:32.738+0000] {local_task_job_runner.py:234} INFO - Task exited with return code 1
[2024-02-14T03:34:32.834+0000] {taskinstance.py:3280} INFO - 0 downstream tasks scheduled from follow-on schedule check
[2024-02-14T03:38:06.574+0000] {taskinstance.py:1956} INFO - Dependencies all met for dep_context=non-requeueable deps ti=<TaskInstance: deverlop_model.data_sets scheduled__2024-02-01T01:15:00+00:00 [queued]>
[2024-02-14T03:38:06.583+0000] {taskinstance.py:1956} INFO - Dependencies all met for dep_context=requeueable deps ti=<TaskInstance: deverlop_model.data_sets scheduled__2024-02-01T01:15:00+00:00 [queued]>
[2024-02-14T03:38:06.584+0000] {taskinstance.py:2170} INFO - Starting attempt 1 of 1
[2024-02-14T03:38:06.600+0000] {taskinstance.py:2191} INFO - Executing <Task(DockerOperator): data_sets> on 2024-02-01 01:15:00+00:00
[2024-02-14T03:38:06.608+0000] {standard_task_runner.py:60} INFO - Started process 2834 to run task
[2024-02-14T03:38:06.611+0000] {standard_task_runner.py:87} INFO - Running: ['***', 'tasks', 'run', 'deverlop_model', 'data_sets', 'scheduled__2024-02-01T01:15:00+00:00', '--job-id', '331', '--raw', '--subdir', 'DAGS_FOLDER/task.py', '--cfg-path', '/tmp/tmpg560pgnn']
[2024-02-14T03:38:06.613+0000] {standard_task_runner.py:88} INFO - Job 331: Subtask data_sets
[2024-02-14T03:38:06.654+0000] {task_command.py:423} INFO - Running <TaskInstance: deverlop_model.data_sets scheduled__2024-02-01T01:15:00+00:00 [running]> on host 6e2ff7d2ffd0
[2024-02-14T03:38:06.713+0000] {taskinstance.py:2480} INFO - Exporting env vars: AIRFLOW_CTX_DAG_OWNER='rtn' AIRFLOW_CTX_DAG_ID='deverlop_model' AIRFLOW_CTX_TASK_ID='data_sets' AIRFLOW_CTX_EXECUTION_DATE='2024-02-01T01:15:00+00:00' AIRFLOW_CTX_TRY_NUMBER='1' AIRFLOW_CTX_DAG_RUN_ID='scheduled__2024-02-01T01:15:00+00:00'
[2024-02-14T03:38:06.732+0000] {docker.py:359} INFO - Starting docker container from image python:3.8
[2024-02-14T03:38:06.737+0000] {taskinstance.py:2698} ERROR - Task failed with exception
Traceback (most recent call last):
  File "/home/airflow/.local/lib/python3.8/site-packages/docker/api/client.py", line 265, in _raise_for_status
    response.raise_for_status()
  File "/home/airflow/.local/lib/python3.8/site-packages/requests/models.py", line 1021, in raise_for_status
    raise HTTPError(http_error_msg, response=self)
requests.exceptions.HTTPError: 409 Client Error: Conflict for url: http+docker://localhost/v1.43/containers/create?name=data_sets

The above exception was the direct cause of the following exception:

Traceback (most recent call last):
  File "/home/airflow/.local/lib/python3.8/site-packages/airflow/models/taskinstance.py", line 433, in _execute_task
    result = execute_callable(context=context, **execute_callable_kwargs)
  File "/home/airflow/.local/lib/python3.8/site-packages/airflow/providers/docker/operators/docker.py", line 502, in execute
    return self._run_image()
  File "/home/airflow/.local/lib/python3.8/site-packages/airflow/providers/docker/operators/docker.py", line 376, in _run_image
    return self._run_image_with_mounts(self.mounts, add_tmp_variable=False)
  File "/home/airflow/.local/lib/python3.8/site-packages/airflow/providers/docker/operators/docker.py", line 391, in _run_image_with_mounts
    self.container = self.cli.create_container(
  File "/home/airflow/.local/lib/python3.8/site-packages/docker/api/container.py", line 439, in create_container
    return self.create_container_from_config(config, name, platform)
  File "/home/airflow/.local/lib/python3.8/site-packages/docker/api/container.py", line 456, in create_container_from_config
    return self._result(res, True)
  File "/home/airflow/.local/lib/python3.8/site-packages/docker/api/client.py", line 271, in _result
    self._raise_for_status(response)
  File "/home/airflow/.local/lib/python3.8/site-packages/docker/api/client.py", line 267, in _raise_for_status
    raise create_api_error_from_http_exception(e) from e
  File "/home/airflow/.local/lib/python3.8/site-packages/docker/errors.py", line 39, in create_api_error_from_http_exception
    raise cls(e, response=response, explanation=explanation) from e
docker.errors.APIError: 409 Client Error for http+docker://localhost/v1.43/containers/create?name=data_sets: Conflict ("Conflict. The container name "/data_sets" is already in use by container "7302939a532eeb4fbe33ede163277e207e5dec00731706b35a5fe6bffd47e265". You have to remove (or rename) that container to be able to reuse that name.")
[2024-02-14T03:38:06.745+0000] {taskinstance.py:1138} INFO - Marking task as FAILED. dag_id=deverlop_model, task_id=data_sets, execution_date=20240201T011500, start_date=20240214T033806, end_date=20240214T033806
[2024-02-14T03:38:06.754+0000] {standard_task_runner.py:107} ERROR - Failed to execute job 331 for task data_sets (409 Client Error for http+docker://localhost/v1.43/containers/create?name=data_sets: Conflict ("Conflict. The container name "/data_sets" is already in use by container "7302939a532eeb4fbe33ede163277e207e5dec00731706b35a5fe6bffd47e265". You have to remove (or rename) that container to be able to reuse that name."); 2834)
[2024-02-14T03:38:06.783+0000] {local_task_job_runner.py:234} INFO - Task exited with return code 1
[2024-02-14T03:38:06.804+0000] {taskinstance.py:3280} INFO - 0 downstream tasks scheduled from follow-on schedule check
[2024-02-14T03:39:32.255+0000] {taskinstance.py:1956} INFO - Dependencies all met for dep_context=non-requeueable deps ti=<TaskInstance: deverlop_model.data_sets scheduled__2024-02-01T01:15:00+00:00 [queued]>
[2024-02-14T03:39:32.262+0000] {taskinstance.py:1956} INFO - Dependencies all met for dep_context=requeueable deps ti=<TaskInstance: deverlop_model.data_sets scheduled__2024-02-01T01:15:00+00:00 [queued]>
[2024-02-14T03:39:32.263+0000] {taskinstance.py:2170} INFO - Starting attempt 1 of 1
[2024-02-14T03:39:32.273+0000] {taskinstance.py:2191} INFO - Executing <Task(DockerOperator): data_sets> on 2024-02-01 01:15:00+00:00
[2024-02-14T03:39:32.280+0000] {standard_task_runner.py:60} INFO - Started process 3039 to run task
[2024-02-14T03:39:32.283+0000] {standard_task_runner.py:87} INFO - Running: ['***', 'tasks', 'run', 'deverlop_model', 'data_sets', 'scheduled__2024-02-01T01:15:00+00:00', '--job-id', '385', '--raw', '--subdir', 'DAGS_FOLDER/task.py', '--cfg-path', '/tmp/tmpsk_evnvv']
[2024-02-14T03:39:32.286+0000] {standard_task_runner.py:88} INFO - Job 385: Subtask data_sets
[2024-02-14T03:39:32.329+0000] {task_command.py:423} INFO - Running <TaskInstance: deverlop_model.data_sets scheduled__2024-02-01T01:15:00+00:00 [running]> on host 6e2ff7d2ffd0
[2024-02-14T03:39:32.390+0000] {taskinstance.py:2480} INFO - Exporting env vars: AIRFLOW_CTX_DAG_OWNER='rtn' AIRFLOW_CTX_DAG_ID='deverlop_model' AIRFLOW_CTX_TASK_ID='data_sets' AIRFLOW_CTX_EXECUTION_DATE='2024-02-01T01:15:00+00:00' AIRFLOW_CTX_TRY_NUMBER='1' AIRFLOW_CTX_DAG_RUN_ID='scheduled__2024-02-01T01:15:00+00:00'
[2024-02-14T03:39:32.405+0000] {docker.py:359} INFO - Starting docker container from image python:3.8
[2024-02-14T03:39:32.409+0000] {taskinstance.py:2698} ERROR - Task failed with exception
Traceback (most recent call last):
  File "/home/airflow/.local/lib/python3.8/site-packages/docker/api/client.py", line 265, in _raise_for_status
    response.raise_for_status()
  File "/home/airflow/.local/lib/python3.8/site-packages/requests/models.py", line 1021, in raise_for_status
    raise HTTPError(http_error_msg, response=self)
requests.exceptions.HTTPError: 409 Client Error: Conflict for url: http+docker://localhost/v1.43/containers/create?name=data_sets

The above exception was the direct cause of the following exception:

Traceback (most recent call last):
  File "/home/airflow/.local/lib/python3.8/site-packages/airflow/models/taskinstance.py", line 433, in _execute_task
    result = execute_callable(context=context, **execute_callable_kwargs)
  File "/home/airflow/.local/lib/python3.8/site-packages/airflow/providers/docker/operators/docker.py", line 502, in execute
    return self._run_image()
  File "/home/airflow/.local/lib/python3.8/site-packages/airflow/providers/docker/operators/docker.py", line 376, in _run_image
    return self._run_image_with_mounts(self.mounts, add_tmp_variable=False)
  File "/home/airflow/.local/lib/python3.8/site-packages/airflow/providers/docker/operators/docker.py", line 391, in _run_image_with_mounts
    self.container = self.cli.create_container(
  File "/home/airflow/.local/lib/python3.8/site-packages/docker/api/container.py", line 439, in create_container
    return self.create_container_from_config(config, name, platform)
  File "/home/airflow/.local/lib/python3.8/site-packages/docker/api/container.py", line 456, in create_container_from_config
    return self._result(res, True)
  File "/home/airflow/.local/lib/python3.8/site-packages/docker/api/client.py", line 271, in _result
    self._raise_for_status(response)
  File "/home/airflow/.local/lib/python3.8/site-packages/docker/api/client.py", line 267, in _raise_for_status
    raise create_api_error_from_http_exception(e) from e
  File "/home/airflow/.local/lib/python3.8/site-packages/docker/errors.py", line 39, in create_api_error_from_http_exception
    raise cls(e, response=response, explanation=explanation) from e
docker.errors.APIError: 409 Client Error for http+docker://localhost/v1.43/containers/create?name=data_sets: Conflict ("Conflict. The container name "/data_sets" is already in use by container "33af6d28a2541e7971c878b23be5daa60420e9e541b4fa61cf521dbd9db46c50". You have to remove (or rename) that container to be able to reuse that name.")
[2024-02-14T03:39:32.417+0000] {taskinstance.py:1138} INFO - Marking task as FAILED. dag_id=deverlop_model, task_id=data_sets, execution_date=20240201T011500, start_date=20240214T033932, end_date=20240214T033932
[2024-02-14T03:39:32.426+0000] {standard_task_runner.py:107} ERROR - Failed to execute job 385 for task data_sets (409 Client Error for http+docker://localhost/v1.43/containers/create?name=data_sets: Conflict ("Conflict. The container name "/data_sets" is already in use by container "33af6d28a2541e7971c878b23be5daa60420e9e541b4fa61cf521dbd9db46c50". You have to remove (or rename) that container to be able to reuse that name."); 3039)
[2024-02-14T03:39:32.456+0000] {local_task_job_runner.py:234} INFO - Task exited with return code 1
[2024-02-14T03:39:32.474+0000] {taskinstance.py:3280} INFO - 0 downstream tasks scheduled from follow-on schedule check
