[2024-02-13T10:12:14.646+0000] {taskinstance.py:1956} INFO - Dependencies all met for dep_context=non-requeueable deps ti=<TaskInstance: deverlop_model.prepare_data_set scheduled__2024-02-13T10:11:00+00:00 [queued]>
[2024-02-13T10:12:14.653+0000] {taskinstance.py:1956} INFO - Dependencies all met for dep_context=requeueable deps ti=<TaskInstance: deverlop_model.prepare_data_set scheduled__2024-02-13T10:11:00+00:00 [queued]>
[2024-02-13T10:12:14.653+0000] {taskinstance.py:2170} INFO - Starting attempt 1 of 1
[2024-02-13T10:12:14.663+0000] {taskinstance.py:2191} INFO - Executing <Task(DockerOperator): prepare_data_set> on 2024-02-13 10:11:00+00:00
[2024-02-13T10:12:14.670+0000] {standard_task_runner.py:60} INFO - Started process 2153 to run task
[2024-02-13T10:12:14.673+0000] {standard_task_runner.py:87} INFO - Running: ['***', 'tasks', 'run', 'deverlop_model', 'prepare_data_set', 'scheduled__2024-02-13T10:11:00+00:00', '--job-id', '399', '--raw', '--subdir', 'DAGS_FOLDER/task.py', '--cfg-path', '/tmp/tmpx3gdn8pp']
[2024-02-13T10:12:14.675+0000] {standard_task_runner.py:88} INFO - Job 399: Subtask prepare_data_set
[2024-02-13T10:12:14.717+0000] {task_command.py:423} INFO - Running <TaskInstance: deverlop_model.prepare_data_set scheduled__2024-02-13T10:11:00+00:00 [running]> on host 292a13d21cb7
[2024-02-13T10:12:14.820+0000] {taskinstance.py:2480} INFO - Exporting env vars: AIRFLOW_CTX_DAG_OWNER='rtn' AIRFLOW_CTX_DAG_ID='deverlop_model' AIRFLOW_CTX_TASK_ID='prepare_data_set' AIRFLOW_CTX_EXECUTION_DATE='2024-02-13T10:11:00+00:00' AIRFLOW_CTX_TRY_NUMBER='1' AIRFLOW_CTX_DAG_RUN_ID='scheduled__2024-02-13T10:11:00+00:00'
[2024-02-13T10:12:14.837+0000] {docker.py:359} INFO - Starting docker container from image python:3.8
[2024-02-13T10:12:19.270+0000] {docker.py:429} INFO - WARNING: Running pip as the 'root' user can result in broken permissions and conflicting behaviour with the system package manager. It is recommended to use a virtual environment instead: https://pip.pypa.io/warnings/venv
[2024-02-13T10:12:19.645+0000] {docker.py:429} INFO - [notice] A new release of pip is available: 23.0.1 -> 24.0
[notice] To update, run: pip install --upgrade pip
[2024-02-13T10:12:24.778+0000] {docker.py:429} INFO - READ DATA :  DataSets : 2024-02-13 10:12:12.042218  timestamp :  2024-02-13 10:12:24.772852
[2024-02-13T10:12:25.222+0000] {taskinstance.py:1138} INFO - Marking task as SUCCESS. dag_id=deverlop_model, task_id=prepare_data_set, execution_date=20240213T101100, start_date=20240213T101214, end_date=20240213T101225
[2024-02-13T10:12:25.276+0000] {local_task_job_runner.py:234} INFO - Task exited with return code 0
[2024-02-13T10:12:25.305+0000] {taskinstance.py:3280} INFO - 2 downstream tasks scheduled from follow-on schedule check
