[2024-02-14T02:07:15.255+0000] {taskinstance.py:1956} INFO - Dependencies all met for dep_context=non-requeueable deps ti=<TaskInstance: deverlop_model.data_sets scheduled__2024-01-01T00:25:00+00:00 [queued]>
[2024-02-14T02:07:15.267+0000] {taskinstance.py:1956} INFO - Dependencies all met for dep_context=requeueable deps ti=<TaskInstance: deverlop_model.data_sets scheduled__2024-01-01T00:25:00+00:00 [queued]>
[2024-02-14T02:07:15.268+0000] {taskinstance.py:2170} INFO - Starting attempt 1 of 1
[2024-02-14T02:07:15.288+0000] {taskinstance.py:2191} INFO - Executing <Task(DockerOperator): data_sets> on 2024-01-01 00:25:00+00:00
[2024-02-14T02:07:15.302+0000] {standard_task_runner.py:60} INFO - Started process 410 to run task
[2024-02-14T02:07:15.323+0000] {standard_task_runner.py:87} INFO - Running: ['***', 'tasks', 'run', 'deverlop_model', 'data_sets', 'scheduled__2024-01-01T00:25:00+00:00', '--job-id', '33', '--raw', '--subdir', 'DAGS_FOLDER/task.py', '--cfg-path', '/tmp/tmpysnqn1t2']
[2024-02-14T02:07:15.326+0000] {standard_task_runner.py:88} INFO - Job 33: Subtask data_sets
[2024-02-14T02:07:15.419+0000] {task_command.py:423} INFO - Running <TaskInstance: deverlop_model.data_sets scheduled__2024-01-01T00:25:00+00:00 [running]> on host 6e2ff7d2ffd0
[2024-02-14T02:07:15.561+0000] {taskinstance.py:2480} INFO - Exporting env vars: AIRFLOW_CTX_DAG_OWNER='rtn' AIRFLOW_CTX_DAG_ID='deverlop_model' AIRFLOW_CTX_TASK_ID='data_sets' AIRFLOW_CTX_EXECUTION_DATE='2024-01-01T00:25:00+00:00' AIRFLOW_CTX_TRY_NUMBER='1' AIRFLOW_CTX_DAG_RUN_ID='scheduled__2024-01-01T00:25:00+00:00'
[2024-02-14T02:07:15.595+0000] {docker.py:359} INFO - Starting docker container from image python:3.8
[2024-02-14T02:07:15.602+0000] {taskinstance.py:2698} ERROR - Task failed with exception
Traceback (most recent call last):
  File "/home/airflow/.local/lib/python3.8/site-packages/docker/api/client.py", line 265, in _raise_for_status
    response.raise_for_status()
  File "/home/airflow/.local/lib/python3.8/site-packages/requests/models.py", line 1021, in raise_for_status
    raise HTTPError(http_error_msg, response=self)
requests.exceptions.HTTPError: 409 Client Error: Conflict for url: http+docker://localhost/v1.43/containers/create?name=data_sets

The above exception was the direct cause of the following exception:

Traceback (most recent call last):
  File "/home/airflow/.local/lib/python3.8/site-packages/airflow/models/taskinstance.py", line 433, in _execute_task
    result = execute_callable(context=context, **execute_callable_kwargs)
  File "/home/airflow/.local/lib/python3.8/site-packages/airflow/providers/docker/operators/docker.py", line 502, in execute
    return self._run_image()
  File "/home/airflow/.local/lib/python3.8/site-packages/airflow/providers/docker/operators/docker.py", line 376, in _run_image
    return self._run_image_with_mounts(self.mounts, add_tmp_variable=False)
  File "/home/airflow/.local/lib/python3.8/site-packages/airflow/providers/docker/operators/docker.py", line 391, in _run_image_with_mounts
    self.container = self.cli.create_container(
  File "/home/airflow/.local/lib/python3.8/site-packages/docker/api/container.py", line 439, in create_container
    return self.create_container_from_config(config, name, platform)
  File "/home/airflow/.local/lib/python3.8/site-packages/docker/api/container.py", line 456, in create_container_from_config
    return self._result(res, True)
  File "/home/airflow/.local/lib/python3.8/site-packages/docker/api/client.py", line 271, in _result
    self._raise_for_status(response)
  File "/home/airflow/.local/lib/python3.8/site-packages/docker/api/client.py", line 267, in _raise_for_status
    raise create_api_error_from_http_exception(e) from e
  File "/home/airflow/.local/lib/python3.8/site-packages/docker/errors.py", line 39, in create_api_error_from_http_exception
    raise cls(e, response=response, explanation=explanation) from e
docker.errors.APIError: 409 Client Error for http+docker://localhost/v1.43/containers/create?name=data_sets: Conflict ("Conflict. The container name "/data_sets" is already in use by container "f661e6f476acc9921c18047679c78f76d8accdecaba0c5595bc6d40f78c57c87". You have to remove (or rename) that container to be able to reuse that name.")
[2024-02-14T02:07:15.626+0000] {taskinstance.py:1138} INFO - Marking task as FAILED. dag_id=deverlop_model, task_id=data_sets, execution_date=20240101T002500, start_date=20240214T020715, end_date=20240214T020715
[2024-02-14T02:07:15.649+0000] {standard_task_runner.py:107} ERROR - Failed to execute job 33 for task data_sets (409 Client Error for http+docker://localhost/v1.43/containers/create?name=data_sets: Conflict ("Conflict. The container name "/data_sets" is already in use by container "f661e6f476acc9921c18047679c78f76d8accdecaba0c5595bc6d40f78c57c87". You have to remove (or rename) that container to be able to reuse that name."); 410)
[2024-02-14T02:07:15.690+0000] {local_task_job_runner.py:234} INFO - Task exited with return code 1
[2024-02-14T02:07:15.732+0000] {taskinstance.py:3280} INFO - 0 downstream tasks scheduled from follow-on schedule check
[2024-02-14T03:53:51.037+0000] {taskinstance.py:1956} INFO - Dependencies all met for dep_context=non-requeueable deps ti=<TaskInstance: deverlop_model.data_sets scheduled__2024-01-01T00:25:00+00:00 [queued]>
[2024-02-14T03:53:51.055+0000] {taskinstance.py:1956} INFO - Dependencies all met for dep_context=requeueable deps ti=<TaskInstance: deverlop_model.data_sets scheduled__2024-01-01T00:25:00+00:00 [queued]>
[2024-02-14T03:53:51.056+0000] {taskinstance.py:2170} INFO - Starting attempt 1 of 1
[2024-02-14T03:53:51.078+0000] {taskinstance.py:2191} INFO - Executing <Task(DockerOperator): data_sets> on 2024-01-01 00:25:00+00:00
[2024-02-14T03:53:51.088+0000] {standard_task_runner.py:60} INFO - Started process 3460 to run task
[2024-02-14T03:53:51.092+0000] {standard_task_runner.py:87} INFO - Running: ['***', 'tasks', 'run', 'deverlop_model', 'data_sets', 'scheduled__2024-01-01T00:25:00+00:00', '--job-id', '442', '--raw', '--subdir', 'DAGS_FOLDER/task.py', '--cfg-path', '/tmp/tmpe6b78bsa']
[2024-02-14T03:53:51.095+0000] {standard_task_runner.py:88} INFO - Job 442: Subtask data_sets
[2024-02-14T03:53:51.155+0000] {task_command.py:423} INFO - Running <TaskInstance: deverlop_model.data_sets scheduled__2024-01-01T00:25:00+00:00 [running]> on host 6e2ff7d2ffd0
[2024-02-14T03:53:51.243+0000] {taskinstance.py:2480} INFO - Exporting env vars: AIRFLOW_CTX_DAG_OWNER='rtn' AIRFLOW_CTX_DAG_ID='deverlop_model' AIRFLOW_CTX_TASK_ID='data_sets' AIRFLOW_CTX_EXECUTION_DATE='2024-01-01T00:25:00+00:00' AIRFLOW_CTX_TRY_NUMBER='1' AIRFLOW_CTX_DAG_RUN_ID='scheduled__2024-01-01T00:25:00+00:00'
[2024-02-14T03:53:51.267+0000] {docker.py:359} INFO - Starting docker container from image python:3.8
[2024-02-14T03:53:51.273+0000] {taskinstance.py:2698} ERROR - Task failed with exception
Traceback (most recent call last):
  File "/home/airflow/.local/lib/python3.8/site-packages/docker/api/client.py", line 265, in _raise_for_status
    response.raise_for_status()
  File "/home/airflow/.local/lib/python3.8/site-packages/requests/models.py", line 1021, in raise_for_status
    raise HTTPError(http_error_msg, response=self)
requests.exceptions.HTTPError: 409 Client Error: Conflict for url: http+docker://localhost/v1.43/containers/create?name=data_sets

The above exception was the direct cause of the following exception:

Traceback (most recent call last):
  File "/home/airflow/.local/lib/python3.8/site-packages/airflow/models/taskinstance.py", line 433, in _execute_task
    result = execute_callable(context=context, **execute_callable_kwargs)
  File "/home/airflow/.local/lib/python3.8/site-packages/airflow/providers/docker/operators/docker.py", line 502, in execute
    return self._run_image()
  File "/home/airflow/.local/lib/python3.8/site-packages/airflow/providers/docker/operators/docker.py", line 376, in _run_image
    return self._run_image_with_mounts(self.mounts, add_tmp_variable=False)
  File "/home/airflow/.local/lib/python3.8/site-packages/airflow/providers/docker/operators/docker.py", line 391, in _run_image_with_mounts
    self.container = self.cli.create_container(
  File "/home/airflow/.local/lib/python3.8/site-packages/docker/api/container.py", line 439, in create_container
    return self.create_container_from_config(config, name, platform)
  File "/home/airflow/.local/lib/python3.8/site-packages/docker/api/container.py", line 456, in create_container_from_config
    return self._result(res, True)
  File "/home/airflow/.local/lib/python3.8/site-packages/docker/api/client.py", line 271, in _result
    self._raise_for_status(response)
  File "/home/airflow/.local/lib/python3.8/site-packages/docker/api/client.py", line 267, in _raise_for_status
    raise create_api_error_from_http_exception(e) from e
  File "/home/airflow/.local/lib/python3.8/site-packages/docker/errors.py", line 39, in create_api_error_from_http_exception
    raise cls(e, response=response, explanation=explanation) from e
docker.errors.APIError: 409 Client Error for http+docker://localhost/v1.43/containers/create?name=data_sets: Conflict ("Conflict. The container name "/data_sets" is already in use by container "517de75a5b6962ac41c5d9b17a26201f8e538ce57b12f724e039342c35cd03d0". You have to remove (or rename) that container to be able to reuse that name.")
[2024-02-14T03:53:51.283+0000] {taskinstance.py:1138} INFO - Marking task as FAILED. dag_id=deverlop_model, task_id=data_sets, execution_date=20240101T002500, start_date=20240214T035351, end_date=20240214T035351
[2024-02-14T03:53:51.297+0000] {standard_task_runner.py:107} ERROR - Failed to execute job 442 for task data_sets (409 Client Error for http+docker://localhost/v1.43/containers/create?name=data_sets: Conflict ("Conflict. The container name "/data_sets" is already in use by container "517de75a5b6962ac41c5d9b17a26201f8e538ce57b12f724e039342c35cd03d0". You have to remove (or rename) that container to be able to reuse that name."); 3460)
[2024-02-14T03:53:51.345+0000] {local_task_job_runner.py:234} INFO - Task exited with return code 1
[2024-02-14T03:53:51.378+0000] {taskinstance.py:3280} INFO - 0 downstream tasks scheduled from follow-on schedule check
[2024-02-14T03:56:03.280+0000] {taskinstance.py:1956} INFO - Dependencies all met for dep_context=non-requeueable deps ti=<TaskInstance: deverlop_model.data_sets scheduled__2024-01-01T00:25:00+00:00 [queued]>
[2024-02-14T03:56:03.297+0000] {taskinstance.py:1956} INFO - Dependencies all met for dep_context=requeueable deps ti=<TaskInstance: deverlop_model.data_sets scheduled__2024-01-01T00:25:00+00:00 [queued]>
[2024-02-14T03:56:03.298+0000] {taskinstance.py:2170} INFO - Starting attempt 1 of 1
[2024-02-14T03:56:03.323+0000] {taskinstance.py:2191} INFO - Executing <Task(DockerOperator): data_sets> on 2024-01-01 00:25:00+00:00
[2024-02-14T03:56:03.339+0000] {standard_task_runner.py:60} INFO - Started process 3587 to run task
[2024-02-14T03:56:03.343+0000] {standard_task_runner.py:87} INFO - Running: ['***', 'tasks', 'run', 'deverlop_model', 'data_sets', 'scheduled__2024-01-01T00:25:00+00:00', '--job-id', '464', '--raw', '--subdir', 'DAGS_FOLDER/task.py', '--cfg-path', '/tmp/tmpisbeb9n5']
[2024-02-14T03:56:03.349+0000] {standard_task_runner.py:88} INFO - Job 464: Subtask data_sets
[2024-02-14T03:56:03.429+0000] {task_command.py:423} INFO - Running <TaskInstance: deverlop_model.data_sets scheduled__2024-01-01T00:25:00+00:00 [running]> on host 6e2ff7d2ffd0
[2024-02-14T03:56:03.550+0000] {taskinstance.py:2480} INFO - Exporting env vars: AIRFLOW_CTX_DAG_OWNER='***' AIRFLOW_CTX_DAG_ID='deverlop_model' AIRFLOW_CTX_TASK_ID='data_sets' AIRFLOW_CTX_EXECUTION_DATE='2024-01-01T00:25:00+00:00' AIRFLOW_CTX_TRY_NUMBER='1' AIRFLOW_CTX_DAG_RUN_ID='scheduled__2024-01-01T00:25:00+00:00'
[2024-02-14T03:56:03.589+0000] {docker.py:359} INFO - Starting docker container from image python:3.8
[2024-02-14T03:56:03.616+0000] {taskinstance.py:2698} ERROR - Task failed with exception
Traceback (most recent call last):
  File "/home/airflow/.local/lib/python3.8/site-packages/docker/api/client.py", line 265, in _raise_for_status
    response.raise_for_status()
  File "/home/airflow/.local/lib/python3.8/site-packages/requests/models.py", line 1021, in raise_for_status
    raise HTTPError(http_error_msg, response=self)
requests.exceptions.HTTPError: 409 Client Error: Conflict for url: http+docker://localhost/v1.43/containers/create?name=data_sets

The above exception was the direct cause of the following exception:

Traceback (most recent call last):
  File "/home/airflow/.local/lib/python3.8/site-packages/airflow/models/taskinstance.py", line 433, in _execute_task
    result = execute_callable(context=context, **execute_callable_kwargs)
  File "/home/airflow/.local/lib/python3.8/site-packages/airflow/providers/docker/operators/docker.py", line 502, in execute
    return self._run_image()
  File "/home/airflow/.local/lib/python3.8/site-packages/airflow/providers/docker/operators/docker.py", line 376, in _run_image
    return self._run_image_with_mounts(self.mounts, add_tmp_variable=False)
  File "/home/airflow/.local/lib/python3.8/site-packages/airflow/providers/docker/operators/docker.py", line 391, in _run_image_with_mounts
    self.container = self.cli.create_container(
  File "/home/airflow/.local/lib/python3.8/site-packages/docker/api/container.py", line 439, in create_container
    return self.create_container_from_config(config, name, platform)
  File "/home/airflow/.local/lib/python3.8/site-packages/docker/api/container.py", line 456, in create_container_from_config
    return self._result(res, True)
  File "/home/airflow/.local/lib/python3.8/site-packages/docker/api/client.py", line 271, in _result
    self._raise_for_status(response)
  File "/home/airflow/.local/lib/python3.8/site-packages/docker/api/client.py", line 267, in _raise_for_status
    raise create_api_error_from_http_exception(e) from e
  File "/home/airflow/.local/lib/python3.8/site-packages/docker/errors.py", line 39, in create_api_error_from_http_exception
    raise cls(e, response=response, explanation=explanation) from e
docker.errors.APIError: 409 Client Error for http+docker://localhost/v1.43/containers/create?name=data_sets: Conflict ("Conflict. The container name "/data_sets" is already in use by container "104e823f5bb6edd84aecdaae8ece217358a6f0121aaf37224b972a491d3a68ce". You have to remove (or rename) that container to be able to reuse that name.")
[2024-02-14T03:56:03.638+0000] {taskinstance.py:1138} INFO - Marking task as FAILED. dag_id=deverlop_model, task_id=data_sets, execution_date=20240101T002500, start_date=20240214T035603, end_date=20240214T035603
[2024-02-14T03:56:03.661+0000] {standard_task_runner.py:107} ERROR - Failed to execute job 464 for task data_sets (409 Client Error for http+docker://localhost/v1.43/containers/create?name=data_sets: Conflict ("Conflict. The container name "/data_sets" is already in use by container "104e823f5bb6edd84aecdaae8ece217358a6f0121aaf37224b972a491d3a68ce". You have to remove (or rename) that container to be able to reuse that name."); 3587)
[2024-02-14T03:56:03.723+0000] {local_task_job_runner.py:234} INFO - Task exited with return code 1
[2024-02-14T03:56:04.543+0000] {taskinstance.py:3280} INFO - 0 downstream tasks scheduled from follow-on schedule check
[2024-02-14T04:00:42.218+0000] {taskinstance.py:1956} INFO - Dependencies all met for dep_context=non-requeueable deps ti=<TaskInstance: deverlop_model.data_sets scheduled__2024-01-01T00:25:00+00:00 [queued]>
[2024-02-14T04:00:42.229+0000] {taskinstance.py:1956} INFO - Dependencies all met for dep_context=requeueable deps ti=<TaskInstance: deverlop_model.data_sets scheduled__2024-01-01T00:25:00+00:00 [queued]>
[2024-02-14T04:00:42.230+0000] {taskinstance.py:2170} INFO - Starting attempt 1 of 1
[2024-02-14T04:00:42.256+0000] {taskinstance.py:2191} INFO - Executing <Task(DockerOperator): data_sets> on 2024-01-01 00:25:00+00:00
[2024-02-14T04:00:42.268+0000] {standard_task_runner.py:60} INFO - Started process 3861 to run task
[2024-02-14T04:00:42.273+0000] {standard_task_runner.py:87} INFO - Running: ['***', 'tasks', 'run', 'deverlop_model', 'data_sets', 'scheduled__2024-01-01T00:25:00+00:00', '--job-id', '526', '--raw', '--subdir', 'DAGS_FOLDER/task.py', '--cfg-path', '/tmp/tmp3h3p0ow1']
[2024-02-14T04:00:42.277+0000] {standard_task_runner.py:88} INFO - Job 526: Subtask data_sets
[2024-02-14T04:00:42.340+0000] {task_command.py:423} INFO - Running <TaskInstance: deverlop_model.data_sets scheduled__2024-01-01T00:25:00+00:00 [running]> on host 6e2ff7d2ffd0
[2024-02-14T04:00:42.430+0000] {taskinstance.py:2480} INFO - Exporting env vars: AIRFLOW_CTX_DAG_OWNER='***' AIRFLOW_CTX_DAG_ID='deverlop_model' AIRFLOW_CTX_TASK_ID='data_sets' AIRFLOW_CTX_EXECUTION_DATE='2024-01-01T00:25:00+00:00' AIRFLOW_CTX_TRY_NUMBER='1' AIRFLOW_CTX_DAG_RUN_ID='scheduled__2024-01-01T00:25:00+00:00'
[2024-02-14T04:00:42.452+0000] {docker.py:359} INFO - Starting docker container from image python:3.8
[2024-02-14T04:00:42.458+0000] {taskinstance.py:2698} ERROR - Task failed with exception
Traceback (most recent call last):
  File "/home/airflow/.local/lib/python3.8/site-packages/docker/api/client.py", line 265, in _raise_for_status
    response.raise_for_status()
  File "/home/airflow/.local/lib/python3.8/site-packages/requests/models.py", line 1021, in raise_for_status
    raise HTTPError(http_error_msg, response=self)
requests.exceptions.HTTPError: 409 Client Error: Conflict for url: http+docker://localhost/v1.43/containers/create?name=data_sets

The above exception was the direct cause of the following exception:

Traceback (most recent call last):
  File "/home/airflow/.local/lib/python3.8/site-packages/airflow/models/taskinstance.py", line 433, in _execute_task
    result = execute_callable(context=context, **execute_callable_kwargs)
  File "/home/airflow/.local/lib/python3.8/site-packages/airflow/providers/docker/operators/docker.py", line 502, in execute
    return self._run_image()
  File "/home/airflow/.local/lib/python3.8/site-packages/airflow/providers/docker/operators/docker.py", line 376, in _run_image
    return self._run_image_with_mounts(self.mounts, add_tmp_variable=False)
  File "/home/airflow/.local/lib/python3.8/site-packages/airflow/providers/docker/operators/docker.py", line 391, in _run_image_with_mounts
    self.container = self.cli.create_container(
  File "/home/airflow/.local/lib/python3.8/site-packages/docker/api/container.py", line 439, in create_container
    return self.create_container_from_config(config, name, platform)
  File "/home/airflow/.local/lib/python3.8/site-packages/docker/api/container.py", line 456, in create_container_from_config
    return self._result(res, True)
  File "/home/airflow/.local/lib/python3.8/site-packages/docker/api/client.py", line 271, in _result
    self._raise_for_status(response)
  File "/home/airflow/.local/lib/python3.8/site-packages/docker/api/client.py", line 267, in _raise_for_status
    raise create_api_error_from_http_exception(e) from e
  File "/home/airflow/.local/lib/python3.8/site-packages/docker/errors.py", line 39, in create_api_error_from_http_exception
    raise cls(e, response=response, explanation=explanation) from e
docker.errors.APIError: 409 Client Error for http+docker://localhost/v1.43/containers/create?name=data_sets: Conflict ("Conflict. The container name "/data_sets" is already in use by container "c144ce272830ce2699e57d068fa5e90b11a79f2f16a986319b478cbdcd44119d". You have to remove (or rename) that container to be able to reuse that name.")
[2024-02-14T04:00:42.470+0000] {taskinstance.py:1138} INFO - Marking task as FAILED. dag_id=deverlop_model, task_id=data_sets, execution_date=20240101T002500, start_date=20240214T040042, end_date=20240214T040042
[2024-02-14T04:00:42.485+0000] {standard_task_runner.py:107} ERROR - Failed to execute job 526 for task data_sets (409 Client Error for http+docker://localhost/v1.43/containers/create?name=data_sets: Conflict ("Conflict. The container name "/data_sets" is already in use by container "c144ce272830ce2699e57d068fa5e90b11a79f2f16a986319b478cbdcd44119d". You have to remove (or rename) that container to be able to reuse that name."); 3861)
[2024-02-14T04:00:42.526+0000] {local_task_job_runner.py:234} INFO - Task exited with return code 1
[2024-02-14T04:00:42.565+0000] {taskinstance.py:3280} INFO - 0 downstream tasks scheduled from follow-on schedule check
