[2024-02-13T08:39:42.719+0000] {taskinstance.py:1956} INFO - Dependencies all met for dep_context=non-requeueable deps ti=<TaskInstance: deverlop_model.prepare_data_set manual__2024-02-13T08:39:31.229121+00:00 [queued]>
[2024-02-13T08:39:42.729+0000] {taskinstance.py:1956} INFO - Dependencies all met for dep_context=requeueable deps ti=<TaskInstance: deverlop_model.prepare_data_set manual__2024-02-13T08:39:31.229121+00:00 [queued]>
[2024-02-13T08:39:42.730+0000] {taskinstance.py:2170} INFO - Starting attempt 1 of 1
[2024-02-13T08:39:42.742+0000] {taskinstance.py:2191} INFO - Executing <Task(DockerOperator): prepare_data_set> on 2024-02-13 08:39:31.229121+00:00
[2024-02-13T08:39:42.750+0000] {standard_task_runner.py:60} INFO - Started process 493 to run task
[2024-02-13T08:39:42.754+0000] {standard_task_runner.py:87} INFO - Running: ['***', 'tasks', 'run', 'deverlop_model', 'prepare_data_set', 'manual__2024-02-13T08:39:31.229121+00:00', '--job-id', '31', '--raw', '--subdir', 'DAGS_FOLDER/task.py', '--cfg-path', '/tmp/tmpv_h_oxg0']
[2024-02-13T08:39:42.756+0000] {standard_task_runner.py:88} INFO - Job 31: Subtask prepare_data_set
[2024-02-13T08:39:42.802+0000] {task_command.py:423} INFO - Running <TaskInstance: deverlop_model.prepare_data_set manual__2024-02-13T08:39:31.229121+00:00 [running]> on host cd7e09605de3
[2024-02-13T08:39:42.878+0000] {taskinstance.py:2480} INFO - Exporting env vars: AIRFLOW_CTX_DAG_OWNER='rtn' AIRFLOW_CTX_DAG_ID='deverlop_model' AIRFLOW_CTX_TASK_ID='prepare_data_set' AIRFLOW_CTX_EXECUTION_DATE='2024-02-13T08:39:31.229121+00:00' AIRFLOW_CTX_TRY_NUMBER='1' AIRFLOW_CTX_DAG_RUN_ID='manual__2024-02-13T08:39:31.229121+00:00'
[2024-02-13T08:39:42.897+0000] {docker.py:359} INFO - Starting docker container from image python:3.8
[2024-02-13T08:39:44.626+0000] {docker.py:429} INFO - WARNING: Running pip as the 'root' user can result in broken permissions and conflicting behaviour with the system package manager. It is recommended to use a virtual environment instead: https://pip.pypa.io/warnings/venv
[2024-02-13T08:39:44.803+0000] {docker.py:429} INFO - [notice] A new release of pip is available: 23.0.1 -> 24.0
[notice] To update, run: pip install --upgrade pip
[2024-02-13T08:39:49.923+0000] {docker.py:429} INFO - READ DATA :  DataSets : 2024-02-13 08:39:41.278274  timestamp :  2024-02-13 08:39:49.920374
[2024-02-13T08:39:50.359+0000] {taskinstance.py:1138} INFO - Marking task as SUCCESS. dag_id=deverlop_model, task_id=prepare_data_set, execution_date=20240213T083931, start_date=20240213T083942, end_date=20240213T083950
[2024-02-13T08:39:50.391+0000] {local_task_job_runner.py:234} INFO - Task exited with return code 0
[2024-02-13T08:39:50.414+0000] {taskinstance.py:3280} INFO - 0 downstream tasks scheduled from follow-on schedule check
