[2024-02-13T10:07:41.963+0000] {taskinstance.py:1956} INFO - Dependencies all met for dep_context=non-requeueable deps ti=<TaskInstance: deverlop_model.prepare_data_set scheduled__2024-02-11T11:40:00+00:00 [queued]>
[2024-02-13T10:07:41.975+0000] {taskinstance.py:1956} INFO - Dependencies all met for dep_context=requeueable deps ti=<TaskInstance: deverlop_model.prepare_data_set scheduled__2024-02-11T11:40:00+00:00 [queued]>
[2024-02-13T10:07:41.976+0000] {taskinstance.py:2170} INFO - Starting attempt 1 of 1
[2024-02-13T10:07:41.992+0000] {taskinstance.py:2191} INFO - Executing <Task(DockerOperator): prepare_data_set> on 2024-02-11 11:40:00+00:00
[2024-02-13T10:07:42.002+0000] {standard_task_runner.py:60} INFO - Started process 1628 to run task
[2024-02-13T10:07:42.006+0000] {standard_task_runner.py:87} INFO - Running: ['***', 'tasks', 'run', 'deverlop_model', 'prepare_data_set', 'scheduled__2024-02-11T11:40:00+00:00', '--job-id', '267', '--raw', '--subdir', 'DAGS_FOLDER/task.py', '--cfg-path', '/tmp/tmpv44y3_4r']
[2024-02-13T10:07:42.010+0000] {standard_task_runner.py:88} INFO - Job 267: Subtask prepare_data_set
[2024-02-13T10:07:42.065+0000] {task_command.py:423} INFO - Running <TaskInstance: deverlop_model.prepare_data_set scheduled__2024-02-11T11:40:00+00:00 [running]> on host 292a13d21cb7
[2024-02-13T10:07:42.154+0000] {taskinstance.py:2480} INFO - Exporting env vars: AIRFLOW_CTX_DAG_OWNER='rtn' AIRFLOW_CTX_DAG_ID='deverlop_model' AIRFLOW_CTX_TASK_ID='prepare_data_set' AIRFLOW_CTX_EXECUTION_DATE='2024-02-11T11:40:00+00:00' AIRFLOW_CTX_TRY_NUMBER='1' AIRFLOW_CTX_DAG_RUN_ID='scheduled__2024-02-11T11:40:00+00:00'
[2024-02-13T10:07:42.178+0000] {docker.py:359} INFO - Starting docker container from image python:3.8
[2024-02-13T10:07:42.184+0000] {taskinstance.py:2698} ERROR - Task failed with exception
Traceback (most recent call last):
  File "/home/airflow/.local/lib/python3.8/site-packages/docker/api/client.py", line 265, in _raise_for_status
    response.raise_for_status()
  File "/home/airflow/.local/lib/python3.8/site-packages/requests/models.py", line 1021, in raise_for_status
    raise HTTPError(http_error_msg, response=self)
requests.exceptions.HTTPError: 409 Client Error: Conflict for url: http+docker://localhost/v1.43/containers/create?name=prepare_data_set

The above exception was the direct cause of the following exception:

Traceback (most recent call last):
  File "/home/airflow/.local/lib/python3.8/site-packages/airflow/models/taskinstance.py", line 433, in _execute_task
    result = execute_callable(context=context, **execute_callable_kwargs)
  File "/home/airflow/.local/lib/python3.8/site-packages/airflow/providers/docker/operators/docker.py", line 502, in execute
    return self._run_image()
  File "/home/airflow/.local/lib/python3.8/site-packages/airflow/providers/docker/operators/docker.py", line 376, in _run_image
    return self._run_image_with_mounts(self.mounts, add_tmp_variable=False)
  File "/home/airflow/.local/lib/python3.8/site-packages/airflow/providers/docker/operators/docker.py", line 391, in _run_image_with_mounts
    self.container = self.cli.create_container(
  File "/home/airflow/.local/lib/python3.8/site-packages/docker/api/container.py", line 439, in create_container
    return self.create_container_from_config(config, name, platform)
  File "/home/airflow/.local/lib/python3.8/site-packages/docker/api/container.py", line 456, in create_container_from_config
    return self._result(res, True)
  File "/home/airflow/.local/lib/python3.8/site-packages/docker/api/client.py", line 271, in _result
    self._raise_for_status(response)
  File "/home/airflow/.local/lib/python3.8/site-packages/docker/api/client.py", line 267, in _raise_for_status
    raise create_api_error_from_http_exception(e) from e
  File "/home/airflow/.local/lib/python3.8/site-packages/docker/errors.py", line 39, in create_api_error_from_http_exception
    raise cls(e, response=response, explanation=explanation) from e
docker.errors.APIError: 409 Client Error for http+docker://localhost/v1.43/containers/create?name=prepare_data_set: Conflict ("Conflict. The container name "/prepare_data_set" is already in use by container "63fa5eafa4743438f4f6c2b21616918d7ed88f9752649e240c567d291c722955". You have to remove (or rename) that container to be able to reuse that name.")
[2024-02-13T10:07:42.194+0000] {taskinstance.py:1138} INFO - Marking task as FAILED. dag_id=deverlop_model, task_id=prepare_data_set, execution_date=20240211T114000, start_date=20240213T100741, end_date=20240213T100742
[2024-02-13T10:07:42.211+0000] {standard_task_runner.py:107} ERROR - Failed to execute job 267 for task prepare_data_set (409 Client Error for http+docker://localhost/v1.43/containers/create?name=prepare_data_set: Conflict ("Conflict. The container name "/prepare_data_set" is already in use by container "63fa5eafa4743438f4f6c2b21616918d7ed88f9752649e240c567d291c722955". You have to remove (or rename) that container to be able to reuse that name."); 1628)
[2024-02-13T10:07:42.259+0000] {local_task_job_runner.py:234} INFO - Task exited with return code 1
[2024-02-13T10:07:42.289+0000] {taskinstance.py:3280} INFO - 0 downstream tasks scheduled from follow-on schedule check
