[2024-02-14T03:34:51.542+0000] {taskinstance.py:1956} INFO - Dependencies all met for dep_context=non-requeueable deps ti=<TaskInstance: deverlop_model.prepare_data_set scheduled__2024-02-01T01:35:00+00:00 [queued]>
[2024-02-14T03:34:51.548+0000] {taskinstance.py:1956} INFO - Dependencies all met for dep_context=requeueable deps ti=<TaskInstance: deverlop_model.prepare_data_set scheduled__2024-02-01T01:35:00+00:00 [queued]>
[2024-02-14T03:34:51.549+0000] {taskinstance.py:2170} INFO - Starting attempt 1 of 1
[2024-02-14T03:34:51.560+0000] {taskinstance.py:2191} INFO - Executing <Task(DockerOperator): prepare_data_set> on 2024-02-01 01:35:00+00:00
[2024-02-14T03:34:51.568+0000] {standard_task_runner.py:60} INFO - Started process 2651 to run task
[2024-02-14T03:34:51.570+0000] {standard_task_runner.py:87} INFO - Running: ['***', 'tasks', 'run', 'deverlop_model', 'prepare_data_set', 'scheduled__2024-02-01T01:35:00+00:00', '--job-id', '293', '--raw', '--subdir', 'DAGS_FOLDER/task.py', '--cfg-path', '/tmp/tmpwuf_d617']
[2024-02-14T03:34:51.573+0000] {standard_task_runner.py:88} INFO - Job 293: Subtask prepare_data_set
[2024-02-14T03:34:51.613+0000] {task_command.py:423} INFO - Running <TaskInstance: deverlop_model.prepare_data_set scheduled__2024-02-01T01:35:00+00:00 [running]> on host 6e2ff7d2ffd0
[2024-02-14T03:34:51.687+0000] {taskinstance.py:2480} INFO - Exporting env vars: AIRFLOW_CTX_DAG_OWNER='rtn' AIRFLOW_CTX_DAG_ID='deverlop_model' AIRFLOW_CTX_TASK_ID='prepare_data_set' AIRFLOW_CTX_EXECUTION_DATE='2024-02-01T01:35:00+00:00' AIRFLOW_CTX_TRY_NUMBER='1' AIRFLOW_CTX_DAG_RUN_ID='scheduled__2024-02-01T01:35:00+00:00'
[2024-02-14T03:34:51.704+0000] {docker.py:359} INFO - Starting docker container from image python:3.8
[2024-02-14T03:34:53.389+0000] {docker.py:429} INFO - WARNING: Running pip as the 'root' user can result in broken permissions and conflicting behaviour with the system package manager. It is recommended to use a virtual environment instead: https://pip.pypa.io/warnings/venv
[2024-02-14T03:34:53.556+0000] {docker.py:429} INFO - [notice] A new release of pip is available: 23.0.1 -> 24.0
[notice] To update, run: pip install --upgrade pip
[2024-02-14T03:34:58.655+0000] {docker.py:429} INFO - READ DATA :  DataSets : 2024-02-14 03:34:49.550420  timestamp :  2024-02-14 03:34:58.650750
[2024-02-14T03:34:59.149+0000] {taskinstance.py:1138} INFO - Marking task as SUCCESS. dag_id=deverlop_model, task_id=prepare_data_set, execution_date=20240201T013500, start_date=20240214T033451, end_date=20240214T033459
[2024-02-14T03:34:59.174+0000] {local_task_job_runner.py:234} INFO - Task exited with return code 0
[2024-02-14T03:34:59.191+0000] {taskinstance.py:3280} INFO - 2 downstream tasks scheduled from follow-on schedule check
