[2024-02-13T18:09:03.177+0000] {taskinstance.py:1956} INFO - Dependencies all met for dep_context=non-requeueable deps ti=<TaskInstance: deverlop_model.data_sets scheduled__2024-02-13T18:00:00+00:00 [queued]>
[2024-02-13T18:09:03.185+0000] {taskinstance.py:1956} INFO - Dependencies all met for dep_context=requeueable deps ti=<TaskInstance: deverlop_model.data_sets scheduled__2024-02-13T18:00:00+00:00 [queued]>
[2024-02-13T18:09:03.186+0000] {taskinstance.py:2170} INFO - Starting attempt 1 of 1
[2024-02-13T18:09:03.206+0000] {taskinstance.py:2191} INFO - Executing <Task(DockerOperator): data_sets> on 2024-02-13 18:00:00+00:00
[2024-02-13T18:09:03.218+0000] {standard_task_runner.py:60} INFO - Started process 102 to run task
[2024-02-13T18:09:03.222+0000] {standard_task_runner.py:87} INFO - Running: ['***', 'tasks', 'run', 'deverlop_model', 'data_sets', 'scheduled__2024-02-13T18:00:00+00:00', '--job-id', '4', '--raw', '--subdir', 'DAGS_FOLDER/task.py', '--cfg-path', '/tmp/tmplk_mk6_u']
[2024-02-13T18:09:03.225+0000] {standard_task_runner.py:88} INFO - Job 4: Subtask data_sets
[2024-02-13T18:09:03.286+0000] {task_command.py:423} INFO - Running <TaskInstance: deverlop_model.data_sets scheduled__2024-02-13T18:00:00+00:00 [running]> on host 4a5aad6d7b9e
[2024-02-13T18:09:03.384+0000] {taskinstance.py:2480} INFO - Exporting env vars: AIRFLOW_CTX_DAG_OWNER='rtn' AIRFLOW_CTX_DAG_ID='deverlop_model' AIRFLOW_CTX_TASK_ID='data_sets' AIRFLOW_CTX_EXECUTION_DATE='2024-02-13T18:00:00+00:00' AIRFLOW_CTX_TRY_NUMBER='1' AIRFLOW_CTX_DAG_RUN_ID='scheduled__2024-02-13T18:00:00+00:00'
[2024-02-13T18:09:03.405+0000] {docker.py:486} INFO - Pulling docker image python:3.8
[2024-02-13T18:09:08.729+0000] {docker.py:500} INFO - 3.8: Pulling from library/python
[2024-02-13T18:09:10.043+0000] {docker.py:500} INFO - 7bb465c29149: Pulling fs layer
[2024-02-13T18:09:10.044+0000] {docker.py:500} INFO - 2b9b41aaa3c5: Pulling fs layer
[2024-02-13T18:09:10.045+0000] {docker.py:500} INFO - 49b40be4436e: Pulling fs layer
[2024-02-13T18:09:10.045+0000] {docker.py:500} INFO - c558fac597f8: Pulling fs layer
[2024-02-13T18:09:10.046+0000] {docker.py:500} INFO - 11402150a57e: Pulling fs layer
[2024-02-13T18:09:10.046+0000] {docker.py:500} INFO - 4532b04ec8f7: Pulling fs layer
[2024-02-13T18:09:10.047+0000] {docker.py:500} INFO - c558fac597f8: Waiting
[2024-02-13T18:09:10.047+0000] {docker.py:500} INFO - 11402150a57e: Waiting
[2024-02-13T18:09:10.048+0000] {docker.py:500} INFO - 4df0efb76c10: Pulling fs layer
[2024-02-13T18:09:10.048+0000] {docker.py:500} INFO - 4532b04ec8f7: Waiting
[2024-02-13T18:09:10.049+0000] {docker.py:500} INFO - 951fd003e72c: Pulling fs layer
[2024-02-13T18:09:10.049+0000] {docker.py:500} INFO - 951fd003e72c: Waiting
[2024-02-13T18:09:10.050+0000] {docker.py:500} INFO - 4df0efb76c10: Waiting
[2024-02-13T18:09:11.694+0000] {docker.py:500} INFO - 2b9b41aaa3c5: Downloading
[2024-02-13T18:09:11.979+0000] {docker.py:500} INFO - 7bb465c29149: Downloading
[2024-02-13T18:09:12.013+0000] {docker.py:500} INFO - 49b40be4436e: Downloading
[2024-02-13T18:09:43.337+0000] {docker.py:500} INFO - 7bb465c29149: Verifying Checksum
[2024-02-13T18:09:43.338+0000] {docker.py:500} INFO - 7bb465c29149: Download complete
[2024-02-13T18:09:43.586+0000] {docker.py:500} INFO - 7bb465c29149: Extracting
[2024-02-13T18:09:46.665+0000] {docker.py:500} INFO - 7bb465c29149: Pull complete
[2024-02-13T18:09:47.552+0000] {docker.py:500} INFO - c558fac597f8: Downloading
[2024-02-13T18:09:53.875+0000] {docker.py:500} INFO - 2b9b41aaa3c5: Verifying Checksum
[2024-02-13T18:09:53.876+0000] {docker.py:500} INFO - 2b9b41aaa3c5: Download complete
[2024-02-13T18:09:58.110+0000] {docker.py:500} INFO - 2b9b41aaa3c5: Extracting
[2024-02-13T18:09:58.427+0000] {docker.py:500} INFO - 11402150a57e: Downloading
[2024-02-13T18:10:05.351+0000] {docker.py:500} INFO - 11402150a57e: Verifying Checksum
[2024-02-13T18:10:05.353+0000] {docker.py:500} INFO - 11402150a57e: Download complete
[2024-02-13T18:10:05.579+0000] {docker.py:500} INFO - 2b9b41aaa3c5: Pull complete
[2024-02-13T18:10:09.623+0000] {docker.py:500} INFO - 4532b04ec8f7: Downloading
[2024-02-13T18:10:22.640+0000] {docker.py:500} INFO - 4532b04ec8f7: Verifying Checksum
[2024-02-13T18:10:22.641+0000] {docker.py:500} INFO - 4532b04ec8f7: Download complete
[2024-02-13T18:10:26.013+0000] {docker.py:500} INFO - 4df0efb76c10: Verifying Checksum
[2024-02-13T18:10:26.014+0000] {docker.py:500} INFO - 4df0efb76c10: Download complete
[2024-02-13T18:10:28.974+0000] {docker.py:500} INFO - 951fd003e72c: Downloading
[2024-02-13T18:10:34.201+0000] {docker.py:500} INFO - 951fd003e72c: Verifying Checksum
[2024-02-13T18:10:34.202+0000] {docker.py:500} INFO - 951fd003e72c: Download complete
[2024-02-13T18:11:00.160+0000] {docker.py:500} INFO - 49b40be4436e: Verifying Checksum
[2024-02-13T18:11:00.161+0000] {docker.py:500} INFO - 49b40be4436e: Download complete
[2024-02-13T18:11:00.283+0000] {docker.py:500} INFO - 49b40be4436e: Extracting
[2024-02-13T18:11:19.687+0000] {docker.py:500} INFO - 49b40be4436e: Pull complete
[2024-02-13T18:11:31.403+0000] {docker.py:500} INFO - c558fac597f8: Verifying Checksum
[2024-02-13T18:11:31.404+0000] {docker.py:500} INFO - c558fac597f8: Download complete
[2024-02-13T18:11:31.499+0000] {docker.py:500} INFO - c558fac597f8: Extracting
[2024-02-13T18:12:19.798+0000] {docker.py:500} INFO - c558fac597f8: Pull complete
[2024-02-13T18:12:19.806+0000] {docker.py:500} INFO - 11402150a57e: Extracting
[2024-02-13T18:12:20.127+0000] {docker.py:500} INFO - 11402150a57e: Pull complete
[2024-02-13T18:12:20.144+0000] {docker.py:500} INFO - 4532b04ec8f7: Extracting
[2024-02-13T18:12:20.767+0000] {docker.py:500} INFO - 4532b04ec8f7: Pull complete
[2024-02-13T18:12:20.771+0000] {docker.py:500} INFO - 4df0efb76c10: Extracting
[2024-02-13T18:12:20.792+0000] {docker.py:500} INFO - 4df0efb76c10: Pull complete
[2024-02-13T18:12:20.797+0000] {docker.py:500} INFO - 951fd003e72c: Extracting
[2024-02-13T18:12:21.095+0000] {docker.py:500} INFO - 951fd003e72c: Pull complete
[2024-02-13T18:12:21.124+0000] {docker.py:495} INFO - Digest: sha256:6150a41f1a0913ccbd5eb52fa12b90228e36286ef3255e6f5c5496d114ab955d
[2024-02-13T18:12:21.128+0000] {docker.py:495} INFO - Status: Downloaded newer image for python:3.8
[2024-02-13T18:12:21.133+0000] {docker.py:359} INFO - Starting docker container from image python:3.8
[2024-02-13T18:12:21.143+0000] {taskinstance.py:2698} ERROR - Task failed with exception
Traceback (most recent call last):
  File "/home/airflow/.local/lib/python3.8/site-packages/docker/api/client.py", line 265, in _raise_for_status
    response.raise_for_status()
  File "/home/airflow/.local/lib/python3.8/site-packages/requests/models.py", line 1021, in raise_for_status
    raise HTTPError(http_error_msg, response=self)
requests.exceptions.HTTPError: 409 Client Error: Conflict for url: http+docker://localhost/v1.43/containers/create?name=data_sets

The above exception was the direct cause of the following exception:

Traceback (most recent call last):
  File "/home/airflow/.local/lib/python3.8/site-packages/airflow/models/taskinstance.py", line 433, in _execute_task
    result = execute_callable(context=context, **execute_callable_kwargs)
  File "/home/airflow/.local/lib/python3.8/site-packages/airflow/providers/docker/operators/docker.py", line 502, in execute
    return self._run_image()
  File "/home/airflow/.local/lib/python3.8/site-packages/airflow/providers/docker/operators/docker.py", line 376, in _run_image
    return self._run_image_with_mounts(self.mounts, add_tmp_variable=False)
  File "/home/airflow/.local/lib/python3.8/site-packages/airflow/providers/docker/operators/docker.py", line 391, in _run_image_with_mounts
    self.container = self.cli.create_container(
  File "/home/airflow/.local/lib/python3.8/site-packages/docker/api/container.py", line 439, in create_container
    return self.create_container_from_config(config, name, platform)
  File "/home/airflow/.local/lib/python3.8/site-packages/docker/api/container.py", line 456, in create_container_from_config
    return self._result(res, True)
  File "/home/airflow/.local/lib/python3.8/site-packages/docker/api/client.py", line 271, in _result
    self._raise_for_status(response)
  File "/home/airflow/.local/lib/python3.8/site-packages/docker/api/client.py", line 267, in _raise_for_status
    raise create_api_error_from_http_exception(e) from e
  File "/home/airflow/.local/lib/python3.8/site-packages/docker/errors.py", line 39, in create_api_error_from_http_exception
    raise cls(e, response=response, explanation=explanation) from e
docker.errors.APIError: 409 Client Error for http+docker://localhost/v1.43/containers/create?name=data_sets: Conflict ("Conflict. The container name "/data_sets" is already in use by container "94ce0a9bfbcd9b03c18bb782b7bcb6214d088a7c48eaa83240ad002f785c550e". You have to remove (or rename) that container to be able to reuse that name.")
[2024-02-13T18:12:21.158+0000] {taskinstance.py:1138} INFO - Marking task as FAILED. dag_id=deverlop_model, task_id=data_sets, execution_date=20240213T180000, start_date=20240213T180903, end_date=20240213T181221
[2024-02-13T18:12:21.228+0000] {standard_task_runner.py:107} ERROR - Failed to execute job 4 for task data_sets (409 Client Error for http+docker://localhost/v1.43/containers/create?name=data_sets: Conflict ("Conflict. The container name "/data_sets" is already in use by container "94ce0a9bfbcd9b03c18bb782b7bcb6214d088a7c48eaa83240ad002f785c550e". You have to remove (or rename) that container to be able to reuse that name."); 102)
[2024-02-13T18:12:21.310+0000] {local_task_job_runner.py:234} INFO - Task exited with return code 1
[2024-02-13T18:12:21.565+0000] {taskinstance.py:3280} INFO - 0 downstream tasks scheduled from follow-on schedule check
